Workbook

Sheet Hướng dẫn
A1: THU CHI GIA ĐÌNH – MẸ VÂN
A3: CÁCH DÙNG
A4: 1. Mỗi khoản thu/chi nhập 1 dòng ở sheet "Sổ giao dịch": Ngày, Nhóm, Danh mục (chọn từ danh sách), Diễn giải, Thu hoặc Chi.
A5: 2. Cột "Tháng" tự tính – không cần nhập.
A6: 3. Sheet "Thống kê tháng": gõ NĂM vào ô vàng → tự tính thu, chi, tồn, tồn lũy kế, tỷ lệ tiết kiệm từng tháng + biểu đồ.
A7: 4. Sheet "Theo danh mục": chi từng danh mục theo 12 tháng, so với ngân sách.
A8: 5. Sheet "Báo cáo tháng": gõ THÁNG và NĂM vào ô vàng → xem tổng hợp và ngân sách của tháng đó.
A9: 6. Sheet "Danh mục": thêm/sửa danh mục và ngân sách mỗi tháng (ô vàng).
A11: QUY ƯỚC
A12: • Ô nền vàng: ô người dùng nhập/sửa. • Các ô khác có công thức – không xóa.
A13: • Số tiền nhập số nguyên (vd 3000000), Excel tự hiện 3,000,000.
A14: • Dữ liệu tháng 8/2026 đã nhập sẵn làm mẫu (lấy từ bảng THU CHI THÁNG 8/2026 của gia đình).
A15: • File này cũng nhập được vào app Thu Chi: app → Lịch sử → "Nhập từ Excel" → chọn file → sheet "Sổ giao dịch".

Sheet Báo cáo tháng
A1: BÁO CÁO THU CHI THÁNG
A2: Tháng: | B2: 8 | C2: Năm: | D2: 2026 | F2: =D2*100+B2
A5: Tổng thu | B5: =SUMIFS('Sổ giao dịch'!$E$2:$E$3001,'Sổ giao dịch'!$H$2:$H$3001,$F$2) | H5: Gõ tháng (1–12) và năm vào ô vàng ở dòng 2.
A6: Tổng chi | B6: =SUMIFS('Sổ giao dịch'!$F$2:$F$3001,'Sổ giao dịch'!$H$2:$H$3001,$F$2) | H6: Danh sách giao dịch chi tiết: sheet "Sổ giao dịch" → lọc cột "Tháng".
A7: Chi cố định | B7: =SUMIFS('Sổ giao dịch'!$F$2:$F$3001,'Sổ giao dịch'!$H$2:$H$3001,$F$2,'Sổ giao dịch'!$B$2:$B$3001,"Cố định")
A8: Chi phát sinh | B8: =B6-B7
A9: TỒN (thu − chi) | B9: =B5-B6
A10: Tỷ lệ tiết kiệm | B10: =IF(B5=0,"",B9/B5)
A11: Số giao dịch | B11: =COUNTIFS('Sổ giao dịch'!$H$2:$H$3001,$F$2)
A12: THEO DANH MỤC
A13: Danh mục | B13: Loại | C13: Thực tế | D13: Ngân sách | E13: Còn lại | F13: % đã dùng
A14: =IF('Danh mục'!A2="","",'Danh mục'!A2) | B14: =IF(A14="","",'Danh mục'!B2) | C14: =IF(A14="","",IF(B14="Thu",SUMIFS('Sổ giao dịch'!$E$2:$E$3001,'Sổ giao dịch'!$C$2:$C$3001,A14,'Sổ giao dịch'!$H$2:$H$3001,$F$2),SUMIFS('Sổ giao dịch'!$F$2:$F$3001,'Sổ giao dịch'!$C$2:$C$3001,A14,'Sổ giao dịch'!$H$2:$H$3001,$F$2))) | D14: =IF(OR(A14="",'Danh mục'!C2=""),"",'Danh mục'!C2) | E14: =IF(D14="","",D14-C14) | F14: =IF(OR(D14="",D14=0),"",C14/D14)
A15: =IF('Danh mục'!A3="","",'Danh mục'!A3) | B15: =IF(A15="","",'Danh mục'!B3) | C15: =IF(A15="","",IF(B15="Thu",SUMIFS('Sổ giao dịch'!$E$2:$E$3001,'Sổ giao dịch'!$C$2:$C$3001,A15,'Sổ giao dịch'!$H$2:$H$3001,$F$2),SUMIFS('Sổ giao dịch'!$F$2:$F$3001,'Sổ giao dịch'!$C$2:$C$3001,A15,'Sổ giao dịch'!$H$2:$H$3001,$F$2))) | D15: =IF(OR(A15="",'Danh mục'!C3=""),"",'Danh mục'!C3) | E15: =IF(D15="","",D15-C15) | F15: =IF(OR(D15="",D15=0),"",C15/D15)
A16: =IF('Danh mục'!A4="","",'Danh mục'!A4) | B16: =IF(A16="","",'Danh mục'!B4) | C16: =IF(A16="","",IF(B16="Thu",SUMIFS('Sổ giao dịch'!$E$2:$E$3001,'Sổ giao dịch'!$C$2:$C$3001,A16,'Sổ giao dịch'!$H$2:$H$3001,$F$2),SUMIFS('Sổ giao dịch'!$F$2:$F$3001,'Sổ giao dịch'!$C$2:$C$3001,A16,'Sổ giao dịch'!$H$2:$H$3001,$F$2))) | D16: =IF(OR(A16="",'Danh mục'!C4=""),"",'Danh mục'!C4) | E16: =IF(D16="","",D16-C16) | F16: =IF(OR(D16="",D16=0),"",C16/D16)
A17: =IF('Danh mục'!A5="","",'Danh mục'!A5) | B17: =IF(A17="","",'Danh mục'!B5) | C17: =IF(A17="","",IF(B17="Thu",SUMIFS('Sổ giao dịch'!$E$2:$E$3001,'Sổ giao dịch'!$C$2:$C$3001,A17,'Sổ giao dịch'!$H$2:$H$3001,$F$2),SUMIFS('Sổ giao dịch'!$F$2:$F$3001,'Sổ giao dịch'!$C$2:$C$3001,A17,'Sổ giao dịch'!$H$2:$H$3001,$F$2))) | D17: =IF(OR(A17="",'Danh mục'!C5=""),"",'Danh mục'!C5) | E17: =IF(D17="","",D17-C17) | F17: =IF(OR(D17="",D17=0),"",C17/D17)
A18: =IF('Danh mục'!A6="","",'Danh mục'!A6) | B18: =IF(A18="","",'Danh mục'!B6) | C18: =IF(A18="","",IF(B18="Thu",SUMIFS('Sổ giao dịch'!$E$2:$E$3001,'Sổ giao dịch'!$C$2:$C$3001,A18,'Sổ giao dịch'!$H$2:$H$3001,$F$2),SUMIFS('Sổ giao dịch'!$F$2:$F$3001,'Sổ giao dịch'!$C$2:$C$3001,A18,'Sổ giao dịch'!$H$2:$H$3001,$F$2))) | D18: =IF(OR(A18="",'Danh mục'!C6=""),"",'Danh mục'!C6) | E18: =IF(D18="","",D18-C18) | F18: =IF(OR(D18="",D18=0),"",C18/D18)
A19: =IF('Danh mục'!A7="","",'Danh mục'!A7) | B19: =IF(A19="","",'Danh mục'!B7) | C19: =IF(A19="","",IF(B19="Thu",SUMIFS('Sổ giao dịch'!$E$2:$E$3001,'Sổ giao dịch'!$C$2:$C$3001,A19,'Sổ giao dịch'!$H$2:$H$3001,$F$2),SUMIFS('Sổ giao dịch'!$F$2:$F$3001,'Sổ giao dịch'!$C$2:$C$3001,A19,'Sổ giao dịch'!$H$2:$H$3001,$F$2))) | D19: =IF(OR(A19="",'Danh mục'!C7=""),"",'Danh mục'!C7) | E19: =IF(D19="","",D19-C19) | F19: =IF(OR(D19="",D19=0),"",C19/D19)
A20: =IF('Danh mục'!A8="","",'Danh mục'!A8) | B20: =IF(A20="","",'Danh mục'!B8) | C20: =IF(A20="","",IF(B20="Thu",SUMIFS('Sổ giao dịch'!$E$2:$E$3001,'Sổ giao dịch'!$C$2:$C$3001,A20,'Sổ giao dịch'!$H$2:$H$3001,$F$2),SUMIFS('Sổ giao dịch'!$F$2:$F$3001,'Sổ giao dịch'!$C$2:$C$3001,A20,'Sổ giao dịch'!$H$2:$H$3001,$F$2))) | D20: =IF(OR(A20="",'Danh mục'!C8=""),"",'Danh mục'!C8) | E20: =IF(D20="","",D20-C20) | F20: =IF(OR(D20="",D20=0),"",C20/D20)
A21: =IF('Danh mục'!A9="","",'Danh mục'!A9) | B21: =IF(A21="","",'Danh mục'!B9) | C21: =IF(A21="","",IF(B21="Thu",SUMIFS('Sổ giao dịch'!$E$2:$E$3001,'Sổ giao dịch'!$C$2:$C$3001,A21,'Sổ giao dịch'!$H$2:$H$3001,$F$2),SUMIFS('Sổ giao dịch'!$F$2:$F$3001,'Sổ giao dịch'!$C$2:$C$3001,A21,'Sổ giao dịch'!$H$2:$H$3001,$F$2))) | D21: =IF(OR(A21="",'Danh mục'!C9=""),"",'Danh mục'!C9) | E21: =IF(D21="","",D21-C21) | F21: =IF(OR(D21="",D21=0),"",C21/D21)
A22: =IF('Danh mục'!A10="","",'Danh mục'!A10) | B22: =IF(A22="","",'Danh mục'!B10) | C22: =IF(A22="","",IF(B22="Thu",SUMIFS('Sổ giao dịch'!$E$2:$E$3001,'Sổ giao dịch'!$C$2:$C$3001,A22,'Sổ giao dịch'!$H$2:$H$3001,$F$2),SUMIFS('Sổ giao dịch'!$F$2:$F$3001,'Sổ giao dịch'!$C$2:$C$3001,A22,'Sổ giao dịch'!$H$2:$H$3001,$F$2))) | D22: =IF(OR(A22="",'Danh mục'!C10=""),"",'Danh mục'!C10) | E22: =IF(D22="","",D22-C22) | F22: =IF(OR(D22="",D22=0),"",C22/D22)
A23: =IF('Danh mục'!A11="","",'Danh mục'!A11) | B23: =IF(A23="","",'Danh mục'!B11) | C23: =IF(A23="","",IF(B23="Thu",SUMIFS('Sổ giao dịch'!$E$2:$E$3001,'Sổ giao dịch'!$C$2:$C$3001,A23,'Sổ giao dịch'!$H$2:$H$3001,$F$2),SUMIFS('Sổ giao dịch'!$F$2:$F$3001,'Sổ giao dịch'!$C$2:$C$3001,A23,'Sổ giao dịch'!$H$2:$H$3001,$F$2))) | D23: =IF(OR(A23="",'Danh mục'!C11=""),"",'Danh mục'!C11) | E23: =IF(D23="","",D23-C23) | F23: =IF(OR(D23="",D23=0),"",C23/D23)
A24: =IF('Danh mục'!A12="","",'Danh mục'!A12) | B24: =IF(A24="","",'Danh mục'!B12) | C24: =IF(A24="","",IF(B24="Thu",SUMIFS('Sổ giao dịch'!$E$2:$E$3001,'Sổ giao dịch'!$C$2:$C$3001,A24,'Sổ giao dịch'!$H$2:$H$3001,$F$2),SUMIFS('Sổ giao dịch'!$F$2:$F$3001,'Sổ giao dịch'!$C$2:$C$3001,A24,'Sổ giao dịch'!$H$2:$H$3001,$F$2))) | D24: =IF(OR(A24="",'Danh mục'!C12=""),"",'Danh mục'!C12) | E24: =IF(D24="","",D24-C24) | F24: =IF(OR(D24="",D24=0),"",C24/D24)
A25: =IF('Danh mục'!A13="","",'Danh mục'!A13) | B25: =IF(A25="","",'Danh mục'!B13) | C25: =IF(A25="","",IF(B25="Thu",SUMIFS('Sổ giao dịch'!$E$2:$E$3001,'Sổ giao dịch'!$C$2:$C$3001,A25,'Sổ giao dịch'!$H$2:$H$3001,$F$2),SUMIFS('Sổ giao dịch'!$F$2:$F$3001,'Sổ giao dịch'!$C$2:$C$3001,A25,'Sổ giao dịch'!$H$2:$H$3001,$F$2))) | D25: =IF(OR(A25="",'Danh mục'!C13=""),"",'Danh mục'!C13) | E25: =IF(D25="","",D25-C25) | F25: =IF(OR(D25="",D25=0),"",C25/D25)
... A43: =IF('Danh mục'!A31="","",'Danh mục'!A31) | B43: =IF(A43="","",'Danh mục'!B31) | C43: =IF(A43="","",IF(B43="Thu",SUMIFS('Sổ giao dịch'!$E$2:$E$3001,'Sổ giao dịch'!$C$2:$C$3001,A43,'Sổ giao dịch'!$H$2:$H$3001,$F$2),SUMIFS('Sổ giao dịch'!$F$2:$F$3001,'Sổ giao dịch'!$C$2:$C$3001,A43,'Sổ giao dịch'!$H$2:$H$3001,$F$2))) | D43: =IF(OR(A43="",'Danh mục'!C31=""),"",'Danh mục'!C31) | E43: =IF(D43="","",D43-C43) | F43: =IF(OR(D43="",D43=0),"",C43/D43)

Sheet Sổ giao dịch
A1: Ngày | B1: Nhóm | C1: Danh mục | D1: Diễn giải | E1: Thu | F1: Chi | G1: Ghi chú | H1: Tháng (tự tính)
A2: 46239 | B2: Cố định | C2: Lương & hoa hồng | D2: Lương ck + hoa hồng | E2: 54000000 | H2: =IF(A2="","",YEAR(A2)*100+MONTH(A2))
A3: 46239 | B3: Cố định | C3: Lương & hoa hồng | D3: Lương vk + lãi làm thẻ + vé máy bay | E3: 40851000 | H3: =IF(A3="","",YEAR(A3)*100+MONTH(A3))
A4: 46239 | B4: Cố định | C4: Ăn uống & đi chợ | D4: Chợ + gas | F4: 3000000 | H4: =IF(A4="","",YEAR(A4)*100+MONTH(A4))
A5: 46239 | B5: Cố định | C5: Lãi vay căn hộ FPT | D5: Lãi căn hộ FPT T8 | F5: 8014000 | H5: =IF(A5="","",YEAR(A5)*100+MONTH(A5))
A6: 46239 | B6: Cố định | C6: Bảo hiểm (BHXH) | D6: BHXH T8 | F6: 1540000 | H6: =IF(A6="","",YEAR(A6)*100+MONTH(A6))
A7: 46239 | B7: Cố định | C7: Con cái (Mon) | D7: Học Mon | F7: 1505000 | H7: =IF(A7="","",YEAR(A7)*100+MONTH(A7))
A8: 46239 | B8: Cố định | C8: Con cái (Mon) | D8: Sữa Mon | F8: 562000 | H8: =IF(A8="","",YEAR(A8)*100+MONTH(A8))
A9: 46239 | B9: Cố định | C9: Ăn uống & đi chợ | D9: Ăn | F9: 3556000 | H9: =IF(A9="","",YEAR(A9)*100+MONTH(A9))
A10: 46239 | B10: Cố định | C10: Điện, nước, điện thoại | D10: Card | F10: 240000 | H10: =IF(A10="","",YEAR(A10)*100+MONTH(A10))
A11: 46239 | B11: Cố định | C11: Xăng xe & gửi xe | D11: Xăng ô tô + xe máy | F11: 493000 | H11: =IF(A11="","",YEAR(A11)*100+MONTH(A11))
A12: 46239 | B12: Cố định | C12: Điện, nước, điện thoại | D12: Điện | F12: 1714000 | H12: =IF(A12="","",YEAR(A12)*100+MONTH(A12))
A13: 46239 | B13: Cố định | C13: Xăng xe & gửi xe | D13: Bãi xe T8 | F13: 800000 | H13: =IF(A13="","",YEAR(A13)*100+MONTH(A13))
A14: 46239 | B14: Phát sinh | C14: Giao lưu, ăn nhậu | D14: Nhậu Thùy + A Phụng | F14: 1168000 | H14: =IF(A14="","",YEAR(A14)*100+MONTH(A14))
A15: 46239 | B15: Phát sinh | C15: Mua sắm cá nhân | D15: Đồ ck + đồ Mon + đồ vk | F15: 3277000 | H15: =IF(A15="","",YEAR(A15)*100+MONTH(A15))
... A20: 46246 | B20: Phát sinh | C20: Đóng tiền căn hộ (theo đợt) | D20: Đóng tiền FPT đợt 3 | F20: 83056000 | H20: =IF(A20="","",YEAR(A20)*100+MONTH(A20))
A21: 46246 | B21: Phát sinh | C21: Thu khác / hoàn phí | D21: Hoàn phí thường niên VIB | E21: 1299000 | H21: =IF(A21="","",YEAR(A21)*100+MONTH(A21))
A22: 46250 | B22: Phát sinh | C22: Đồ gia dụng & trả góp | D22: Góp tủ lạnh T2 | F22: 500000 | H22: =IF(A22="","",YEAR(A22)*100+MONTH(A22))
A23: 46250 | B23: Phát sinh | C23: Mua sắm cá nhân | D23: Kem cn, son, kem dưỡng | F23: 800000 | H23: =IF(A23="","",YEAR(A23)*100+MONTH(A23))
A24: 46250 | B24: Phát sinh | C24: Thuốc & sức khỏe | D24: Thuốc | F24: 231000 | H24: =IF(A24="","",YEAR(A24)*100+MONTH(A24))
A25: 46250 | B25: Phát sinh | C25: Đồ gia dụng & trả góp | D25: Ra gối mền | F25: 2779000 | H25: =IF(A25="","",YEAR(A25)*100+MONTH(A25))
A26: 46265 | B26: Phát sinh | C26: Công việc & marketing | D26: Mkt ck | F26: 1000000 | H26: =IF(A26="","",YEAR(A26)*100+MONTH(A26))
H27: =IF(A27="","",YEAR(A27)*100+MONTH(A27))
H28: =IF(A28="","",YEAR(A28)*100+MONTH(A28))
H29: =IF(A29="","",YEAR(A29)*100+MONTH(A29))
H30: =IF(A30="","",YEAR(A30)*100+MONTH(A30))
H31: =IF(A31="","",YEAR(A31)*100+MONTH(A31))
H32: =IF(A32="","",YEAR(A32)*100+MONTH(A32))
H33: =IF(A33="","",YEAR(A33)*100+MONTH(A33))
H34: =IF(A34="","",YEAR(A34)*100+MONTH(A34))
H35: =IF(A35="","",YEAR(A35)*100+MONTH(A35))
H36: =IF(A36="","",YEAR(A36)*100+MONTH(A36))
H37: =IF(A37="","",YEAR(A37)*100+MONTH(A37))
H38: =IF(A38="","",YEAR(A38)*100+MONTH(A38))
... H3001: =IF(A3001="","",YEAR(A3001)*100+MONTH(A3001))

Sheet Thống kê tháng
A1: THỐNG KÊ THU CHI NĂM
A2: Năm: | B2: 2026
A4: Tháng | B4: Tổng thu | C4: Tổng chi | D4: Chi cố định | E4: Chi phát sinh | F4: Tồn (thu − chi) | G4: Tồn lũy kế | H4: Tiết kiệm % | I4: Số giao dịch
A5: T1 | B5: =SUMIFS('Sổ giao dịch'!$E$2:$E$3001,'Sổ giao dịch'!$H$2:$H$3001,($B$2*100+1)) | C5: =SUMIFS('Sổ giao dịch'!$F$2:$F$3001,'Sổ giao dịch'!$H$2:$H$3001,($B$2*100+1)) | D5: =SUMIFS('Sổ giao dịch'!$F$2:$F$3001,'Sổ giao dịch'!$H$2:$H$3001,($B$2*100+1),'Sổ giao dịch'!$B$2:$B$3001,"Cố định") | E5: =C5-D5 | F5: =B5-C5 | G5: =F5 | H5: =IF(B5=0,"",F5/B5) | I5: =COUNTIFS('Sổ giao dịch'!$H$2:$H$3001,($B$2*100+1))
A6: T2 | B6: =SUMIFS('Sổ giao dịch'!$E$2:$E$3001,'Sổ giao dịch'!$H$2:$H$3001,($B$2*100+2)) | C6: =SUMIFS('Sổ giao dịch'!$F$2:$F$3001,'Sổ giao dịch'!$H$2:$H$3001,($B$2*100+2)) | D6: =SUMIFS('Sổ giao dịch'!$F$2:$F$3001,'Sổ giao dịch'!$H$2:$H$3001,($B$2*100+2),'Sổ giao dịch'!$B$2:$B$3001,"Cố định") | E6: =C6-D6 | F6: =B6-C6 | G6: =G5+F6 | H6: =IF(B6=0,"",F6/B6) | I6: =COUNTIFS('Sổ giao dịch'!$H$2:$H$3001,($B$2*100+2))
A7: T3 | B7: =SUMIFS('Sổ giao dịch'!$E$2:$E$3001,'Sổ giao dịch'!$H$2:$H$3001,($B$2*100+3)) | C7: =SUMIFS('Sổ giao dịch'!$F$2:$F$3001,'Sổ giao dịch'!$H$2:$H$3001,($B$2*100+3)) | D7: =SUMIFS('Sổ giao dịch'!$F$2:$F$3001,'Sổ giao dịch'!$H$2:$H$3001,($B$2*100+3),'Sổ giao dịch'!$B$2:$B$3001,"Cố định") | E7: =C7-D7 | F7: =B7-C7 | G7: =G6+F7 | H7: =IF(B7=0,"",F7/B7) | I7: =COUNTIFS('Sổ giao dịch'!$H$2:$H$3001,($B$2*100+3))
A8: T4 | B8: =SUMIFS('Sổ giao dịch'!$E$2:$E$3001,'Sổ giao dịch'!$H$2:$H$3001,($B$2*100+4)) | C8: =SUMIFS('Sổ giao dịch'!$F$2:$F$3001,'Sổ giao dịch'!$H$2:$H$3001,($B$2*100+4)) | D8: =SUMIFS('Sổ giao dịch'!$F$2:$F$3001,'Sổ giao dịch'!$H$2:$H$3001,($B$2*100+4),'Sổ giao dịch'!$B$2:$B$3001,"Cố định") | E8: =C8-D8 | F8: =B8-C8 | G8: =G7+F8 | H8: =IF(B8=0,"",F8/B8) | I8: =COUNTIFS('Sổ giao dịch'!$H$2:$H$3001,($B$2*100+4))
A9: T5 | B9: =SUMIFS('Sổ giao dịch'!$E$2:$E$3001,'Sổ giao dịch'!$H$2:$H$3001,($B$2*100+5)) | C9: =SUMIFS('Sổ giao dịch'!$F$2:$F$3001,'Sổ giao dịch'!$H$2:$H$3001,($B$2*100+5)) | D9: =SUMIFS('Sổ giao dịch'!$F$2:$F$3001,'Sổ giao dịch'!$H$2:$H$3001,($B$2*100+5),'Sổ giao dịch'!$B$2:$B$3001,"Cố định") | E9: =C9-D9 | F9: =B9-C9 | G9: =G8+F9 | H9: =IF(B9=0,"",F9/B9) | I9: =COUNTIFS('Sổ giao dịch'!$H$2:$H$3001,($B$2*100+5))
A10: T6 | B10: =SUMIFS('Sổ giao dịch'!$E$2:$E$3001,'Sổ giao dịch'!$H$2:$H$3001,($B$2*100+6)) | C10: =SUMIFS('Sổ giao dịch'!$F$2:$F$3001,'Sổ giao dịch'!$H$2:$H$3001,($B$2*100+6)) | D10: =SUMIFS('Sổ giao dịch'!$F$2:$F$3001,'Sổ giao dịch'!$H$2:$H$3001,($B$2*100+6),'Sổ giao dịch'!$B$2:$B$3001,"Cố định") | E10: =C10-D10 | F10: =B10-C10 | G10: =G9+F10 | H10: =IF(B10=0,"",F10/B10) | I10: =COUNTIFS('Sổ giao dịch'!$H$2:$H$3001,($B$2*100+6))
A11: T7 | B11: =SUMIFS('Sổ giao dịch'!$E$2:$E$3001,'Sổ giao dịch'!$H$2:$H$3001,($B$2*100+7)) | C11: =SUMIFS('Sổ giao dịch'!$F$2:$F$3001,'Sổ giao dịch'!$H$2:$H$3001,($B$2*100+7)) | D11: =SUMIFS('Sổ giao dịch'!$F$2:$F$3001,'Sổ giao dịch'!$H$2:$H$3001,($B$2*100+7),'Sổ giao dịch'!$B$2:$B$3001,"Cố định") | E11: =C11-D11 | F11: =B11-C11 | G11: =G10+F11 | H11: =IF(B11=0,"",F11/B11) | I11: =COUNTIFS('Sổ giao dịch'!$H$2:$H$3001,($B$2*100+7))
A12: T8 | B12: =SUMIFS('Sổ giao dịch'!$E$2:$E$3001,'Sổ giao dịch'!$H$2:$H$3001,($B$2*100+8)) | C12: =SUMIFS('Sổ giao dịch'!$F$2:$F$3001,'Sổ giao dịch'!$H$2:$H$3001,($B$2*100+8)) | D12: =SUMIFS('Sổ giao dịch'!$F$2:$F$3001,'Sổ giao dịch'!$H$2:$H$3001,($B$2*100+8),'Sổ giao dịch'!$B$2:$B$3001,"Cố định") | E12: =C12-D12 | F12: =B12-C12 | G12: =G11+F12 | H12: =IF(B12=0,"",F12/B12) | I12: =COUNTIFS('Sổ giao dịch'!$H$2:$H$3001,($B$2*100+8))
A13: T9 | B13: =SUMIFS('Sổ giao dịch'!$E$2:$E$3001,'Sổ giao dịch'!$H$2:$H$3001,($B$2*100+9)) | C13: =SUMIFS('Sổ giao dịch'!$F$2:$F$3001,'Sổ giao dịch'!$H$2:$H$3001,($B$2*100+9)) | D13: =SUMIFS('Sổ giao dịch'!$F$2:$F$3001,'Sổ giao dịch'!$H$2:$H$3001,($B$2*100+9),'Sổ giao dịch'!$B$2:$B$3001,"Cố định") | E13: =C13-D13 | F13: =B13-C13 | G13: =G12+F13 | H13: =IF(B13=0,"",F13/B13) | I13: =COUNTIFS('Sổ giao dịch'!$H$2:$H$3001,($B$2*100+9))
A14: T10 | B14: =SUMIFS('Sổ giao dịch'!$E$2:$E$3001,'Sổ giao dịch'!$H$2:$H$3001,($B$2*100+10)) | C14: =SUMIFS('Sổ giao dịch'!$F$2:$F$3001,'Sổ giao dịch'!$H$2:$H$3001,($B$2*100+10)) | D14: =SUMIFS('Sổ giao dịch'!$F$2:$F$3001,'Sổ giao dịch'!$H$2:$H$3001,($B$2*100+10),'Sổ giao dịch'!$B$2:$B$3001,"Cố định") | E14: =C14-D14 | F14: =B14-C14 | G14: =G13+F14 | H14: =IF(B14=0,"",F14/B14) | I14: =COUNTIFS('Sổ giao dịch'!$H$2:$H$3001,($B$2*100+10))
A15: T11 | B15: =SUMIFS('Sổ giao dịch'!$E$2:$E$3001,'Sổ giao dịch'!$H$2:$H$3001,($B$2*100+11)) | C15: =SUMIFS('Sổ giao dịch'!$F$2:$F$3001,'Sổ giao dịch'!$H$2:$H$3001,($B$2*100+11)) | D15: =SUMIFS('Sổ giao dịch'!$F$2:$F$3001,'Sổ giao dịch'!$H$2:$H$3001,($B$2*100+11),'Sổ giao dịch'!$B$2:$B$3001,"Cố định") | E15: =C15-D15 | F15: =B15-C15 | G15: =G14+F15 | H15: =IF(B15=0,"",F15/B15) | I15: =COUNTIFS('Sổ giao dịch'!$H$2:$H$3001,($B$2*100+11))
A16: T12 | B16: =SUMIFS('Sổ giao dịch'!$E$2:$E$3001,'Sổ giao dịch'!$H$2:$H$3001,($B$2*100+12)) | C16: =SUMIFS('Sổ giao dịch'!$F$2:$F$3001,'Sổ giao dịch'!$H$2:$H$3001,($B$2*100+12)) | D16: =SUMIFS('Sổ giao dịch'!$F$2:$F$3001,'Sổ giao dịch'!$H$2:$H$3001,($B$2*100+12),'Sổ giao dịch'!$B$2:$B$3001,"Cố định") | E16: =C16-D16 | F16: =B16-C16 | G16: =G15+F16 | H16: =IF(B16=0,"",F16/B16) | I16: =COUNTIFS('Sổ giao dịch'!$H$2:$H$3001,($B$2*100+12))
A17: CẢ NĂM | B17: =SUM(B5:B16) | C17: =SUM(C5:C16) | D17: =SUM(D5:D16) | E17: =SUM(E5:E16) | F17: =SUM(F5:F16) | G17: =G16 | H17: =IF(B17=0,"",F17/B17) | I17: =SUM(I5:I16)
A19: Số tháng có dữ liệu | B19: =COUNTIF(I5:I16,">0")
A20: Thu trung bình / tháng | B20: =IF(B19=0,0,B17/B19)
A21: Chi trung bình / tháng | B21: =IF(B19=0,0,C17/B19)
A22: Chi nhiều nhất trong 1 tháng | B22: =MAX(C5:C16)
A23: Tháng chi nhiều nhất | B23: =IF(B22=0,"",INDEX(A5:A16,MATCH(B22,C5:C16,0)))

Sheet Theo danh mục
A1: CHI / THU THEO DANH MỤC – NĂM | F1: ='Thống kê tháng'!B2
A2: (Năm lấy theo ô vàng ở sheet "Thống kê tháng")
A4: Danh mục | B4: Loại | C4: T1 | D4: T2 | E4: T3 | F4: T4 | G4: T5 | H4: T6 | I4: T7 | J4: T8 | K4: T9 | L4: T10 | M4: T11 | N4: T12 | O4: Cả năm | P4: TB / tháng | Q4: Ngân sách / tháng | R4: TB so với NS
A5: =IF('Danh mục'!A2="","",'Danh mục'!A2) | B5: =IF(A5="","",'Danh mục'!B2) | C5: =IF(A5="","",IF(B5="Thu",SUMIFS('Sổ giao dịch'!$E$2:$E$3001,'Sổ giao dịch'!$C$2:$C$3001,A5,'Sổ giao dịch'!$H$2:$H$3001,'Thống kê tháng'!$B$2*100+1),SUMIFS('Sổ giao dịch'!$F$2:$F$3001,'Sổ giao dịch'!$C$2:$C$3001,A5,'Sổ giao dịch'!$H$2:$H$3001,'Thống kê tháng'!$B$2*100+1))) | D5: =IF(A5="","",IF(B5="Thu",SUMIFS('Sổ giao dịch'!$E$2:$E$3001,'Sổ giao dịch'!$C$2:$C$3001,A5,'Sổ giao dịch'!$H$2:$H$3001,'Thống kê tháng'!$B$2*100+2),SUMIFS('Sổ giao dịch'!$F$2:$F$3001,'Sổ giao dịch'!$C$2:$C$3001,A5,'Sổ giao dịch'!$H$2:$H$3001,'Thống kê tháng'!$B$2*100+2))) | E5: =IF(A5="","",IF(B5="Thu",SUMIFS('Sổ giao dịch'!$E$2:$E$3001,'Sổ giao dịch'!$C$2:$C$3001,A5,'Sổ giao dịch'!$H$2:$H$3001,'Thống kê tháng'!$B$2*100+3),SUMIFS('Sổ giao dịch'!$F$2:$F$3001,'Sổ giao dịch'!$C$2:$C$3001,A5,'Sổ giao dịch'!$H$2:$H$3001,'Thống kê tháng'!$B$2*100+3))) | F5: =IF(A5="","",IF(B5="Thu",SUMIFS('Sổ giao dịch'!$E$2:$E$3001,'Sổ giao dịch'!$C$2:$C$3001,A5,'Sổ giao dịch'!$H$2:$H$3001,'Thống kê tháng'!$B$2*100+4),SUMIFS('Sổ giao dịch'!$F$2:$F$3001,'Sổ giao dịch'!$C$2:$C$3001,A5,'Sổ giao dịch'!$H$2:$H$3001,'Thống kê tháng'!$B$2*100+4))) | G5: =IF(A5="","",IF(B5="Thu",SUMIFS('Sổ giao dịch'!$E$2:$E$3001,'Sổ giao dịch'!$C$2:$C$3001,A5,'Sổ giao dịch'!$H$2:$H$3001,'Thống kê tháng'!$B$2*100+5),SUMIFS('Sổ giao dịch'!$F$2:$F$3001,'Sổ giao dịch'!$C$2:$C$3001,A5,'Sổ giao dịch'!$H$2:$H$3001,'Thống kê tháng'!$B$2*100+5))) | H5: =IF(A5="","",IF(B5="Thu",SUMIFS('Sổ giao dịch'!$E$2:$E$3001,'Sổ giao dịch'!$C$2:$C$3001,A5,'Sổ giao dịch'!$H$2:$H$3001,'Thống kê tháng'!$B$2*100+6),SUMIFS('Sổ giao dịch'!$F$2:$F$3001,'Sổ giao dịch'!$C$2:$C$3001,A5,'Sổ giao dịch'!$H$2:$H$3001,'Thống kê tháng'!$B$2*100+6))) | I5: =IF(A5="","",IF(B5="Thu",SUMIFS('Sổ giao dịch'!$E$2:$E$3001,'Sổ giao dịch'!$C$2:$C$3001,A5,'Sổ giao dịch'!$H$2:$H$3001,'Thống kê tháng'!$B$2*100+7),SUMIFS('Sổ giao dịch'!$F$2:$F$3001,'Sổ giao dịch'!$C$2:$C$3001,A5,'Sổ giao dịch'!$H$2:$H$3001,'Thống kê tháng'!$B$2*100+7))) | J5: =IF(A5="","",IF(B5="Thu",SUMIFS('Sổ giao dịch'!$E$2:$E$3001,'Sổ giao dịch'!$C$2:$C$3001,A5,'Sổ giao dịch'!$H$2:$H$3001,'Thống kê tháng'!$B$2*100+8),SUMIFS('Sổ giao dịch'!$F$2:$F$3001,'Sổ giao dịch'!$C$2:$C$3001,A5,'Sổ giao dịch'!$H$2:$H$3001,'Thống kê tháng'!$B$2*100+8))) | K5: =IF(A5="","",IF(B5="Thu",SUMIFS('Sổ giao dịch'!$E$2:$E$3001,'Sổ giao dịch'!$C$2:$C$3001,A5,'Sổ giao dịch'!$H$2:$H$3001,'Thống kê tháng'!$B$2*100+9),SUMIFS('Sổ giao dịch'!$F$2:$F$3001,'Sổ giao dịch'!$C$2:$C$3001,A5,'Sổ giao dịch'!$H$2:$H$3001,'Thống kê tháng'!$B$2*100+9))) | L5: =IF(A5="","",IF(B5="Thu",SUMIFS('Sổ giao dịch'!$E$2:$E$3001,'Sổ giao dịch'!$C$2:$C$3001,A5,'Sổ giao dịch'!$H$2:$H$3001,'Thống kê tháng'!$B$2*100+10),SUMIFS('Sổ giao dịch'!$F$2:$F$3001,'Sổ giao dịch'!$C$2:$C$3001,A5,'Sổ giao dịch'!$H$2:$H$3001,'Thống kê tháng'!$B$2*100+10))) | M5: =IF(A5="","",IF(B5="Thu",SUMIFS('Sổ giao dịch'!$E$2:$E$3001,'Sổ giao dịch'!$C$2:$C$3001,A5,'Sổ giao dịch'!$H$2:$H$3001,'Thống kê tháng'!$B$2*100+11),SUMIFS('Sổ giao dịch'!$F$2:$F$3001,'Sổ giao dịch'!$C$2:$C$3001,A5,'Sổ giao dịch'!$H$2:$H$3001,'Thống kê tháng'!$B$2*100+11))) | N5: =IF(A5="","",IF(B5="Thu",SUMIFS('Sổ giao dịch'!$E$2:$E$3001,'Sổ giao dịch'!$C$2:$C$3001,A5,'Sổ giao dịch'!$H$2:$H$3001,'Thống kê tháng'!$B$2*100+12),SUMIFS('Sổ giao dịch'!$F$2:$F$3001,'Sổ giao dịch'!$C$2:$C$3001,A5,'Sổ giao dịch'!$H$2:$H$3001,'Thống kê tháng'!$B$2*100+12))) | O5: =IF(A5="","",SUM(C5:N5)) | P5: =IF(A5="","",IF('Thống kê tháng'!$B$19=0,0,O5/'Thống kê tháng'!$B$19)) | Q5: =IF(OR(A5="",'Danh mục'!C2=""),"",'Danh mục'!C2) | R5: =IF(OR(Q5="",Q5=0),"",P5/Q5)
A6: =IF('Danh mục'!A3="","",'Danh mục'!A3) | B6: =IF(A6="","",'Danh mục'!B3) | C6: =IF(A6="","",IF(B6="Thu",SUMIFS('Sổ giao dịch'!$E$2:$E$3001,'Sổ giao dịch'!$C$2:$C$3001,A6,'Sổ giao dịch'!$H$2:$H$3001,'Thống kê tháng'!$B$2*100+1),SUMIFS('Sổ giao dịch'!$F$2:$F$3001,'Sổ giao dịch'!$C$2:$C$3001,A6,'Sổ giao dịch'!$H$2:$H$3001,'Thống kê tháng'!$B$2*100+1))) | D6: =IF(A6="","",IF(B6="Thu",SUMIFS('Sổ giao dịch'!$E$2:$E$3001,'Sổ giao dịch'!$C$2:$C$3001,A6,'Sổ giao dịch'!$H$2:$H$3001,'Thống kê tháng'!$B$2*100+2),SUMIFS('Sổ giao dịch'!$F$2:$F$3001,'Sổ giao dịch'!$C$2:$C$3001,A6,'Sổ giao dịch'!$H$2:$H$3001,'Thống kê tháng'!$B$2*100+2))) | E6: =IF(A6="","",IF(B6="Thu",SUMIFS('Sổ giao dịch'!$E$2:$E$3001,'Sổ giao dịch'!$C$2:$C$3001,A6,'Sổ giao dịch'!$H$2:$H$3001,'Thống kê tháng'!$B$2*100+3),SUMIFS('Sổ giao dịch'!$F$2:$F$3001,'Sổ giao dịch'!$C$2:$C$3001,A6,'Sổ giao dịch'!$H$2:$H$3001,'Thống kê tháng'!$B$2*100+3))) | F6: =IF(A6="","",IF(B6="Thu",SUMIFS('Sổ giao dịch'!$E$2:$E$3001,'Sổ giao dịch'!$C$2:$C$3001,A6,'Sổ giao dịch'!$H$2:$H$3001,'Thống kê tháng'!$B$2*100+4),SUMIFS('Sổ giao dịch'!$F$2:$F$3001,'Sổ giao dịch'!$C$2:$C$3001,A6,'Sổ giao dịch'!$H$2:$H$3001,'Thống kê tháng'!$B$2*100+4))) | G6: =IF(A6="","",IF(B6="Thu",SUMIFS('Sổ giao dịch'!$E$2:$E$3001,'Sổ giao dịch'!$C$2:$C$3001,A6,'Sổ giao dịch'!$H$2:$H$3001,'Thống kê tháng'!$B$2*100+5),SUMIFS('Sổ giao dịch'!$F$2:$F$3001,'Sổ giao dịch'!$C$2:$C$3001,A6,'Sổ giao dịch'!$H$2:$H$3001,'Thống kê tháng'!$B$2*100+5))) | H6: =IF(A6="","",IF(B6="Thu",SUMIFS('Sổ giao dịch'!$E$2:$E$3001,'Sổ giao dịch'!$C$2:$C$3001,A6,'Sổ giao dịch'!$H$2:$H$3001,'Thống kê tháng'!$B$2*100+6),SUMIFS('Sổ giao dịch'!$F$2:$F$3001,'Sổ giao dịch'!$C$2:$C$3001,A6,'Sổ giao dịch'!$H$2:$H$3001,'Thống kê tháng'!$B$2*100+6))) | I6: =IF(A6="","",IF(B6="Thu",SUMIFS('Sổ giao dịch'!$E$2:$E$3001,'Sổ giao dịch'!$C$2:$C$3001,A6,'Sổ giao dịch'!$H$2:$H$3001,'Thống kê tháng'!$B$2*100+7),SUMIFS('Sổ giao dịch'!$F$2:$F$3001,'Sổ giao dịch'!$C$2:$C$3001,A6,'Sổ giao dịch'!$H$2:$H$3001,'Thống kê tháng'!$B$2*100+7))) | J6: =IF(A6="","",IF(B6="Thu",SUMIFS('Sổ giao dịch'!$E$2:$E$3001,'Sổ giao dịch'!$C$2:$C$3001,A6,'Sổ giao dịch'!$H$2:$H$3001,'Thống kê tháng'!$B$2*100+8),SUMIFS('Sổ giao dịch'!$F$2:$F$3001,'Sổ giao dịch'!$C$2:$C$3001,A6,'Sổ giao dịch'!$H$2:$H$3001,'Thống kê tháng'!$B$2*100+8))) | K6: =IF(A6="","",IF(B6="Thu",SUMIFS('Sổ giao dịch'!$E$2:$E$3001,'Sổ giao dịch'!$C$2:$C$3001,A6,'Sổ giao dịch'!$H$2:$H$3001,'Thống kê tháng'!$B$2*100+9),SUMIFS('Sổ giao dịch'!$F$2:$F$3001,'Sổ giao dịch'!$C$2:$C$3001,A6,'Sổ giao dịch'!$H$2:$H$3001,'Thống kê tháng'!$B$2*100+9))) | L6: =IF(A6="","",IF(B6="Thu",SUMIFS('Sổ giao dịch'!$E$2:$E$3001,'Sổ giao dịch'!$C$2:$C$3001,A6,'Sổ giao dịch'!$H$2:$H$3001,'Thống kê tháng'!$B$2*100+10),SUMIFS('Sổ giao dịch'!$F$2:$F$3001,'Sổ giao dịch'!$C$2:$C$3001,A6,'Sổ giao dịch'!$H$2:$H$3001,'Thống kê tháng'!$B$2*100+10))) | M6: =IF(A6="","",IF(B6="Thu",SUMIFS('Sổ giao dịch'!$E$2:$E$3001,'Sổ giao dịch'!$C$2:$C$3001,A6,'Sổ giao dịch'!$H$2:$H$3001,'Thống kê tháng'!$B$2*100+11),SUMIFS('Sổ giao dịch'!$F$2:$F$3001,'Sổ giao dịch'!$C$2:$C$3001,A6,'Sổ giao dịch'!$H$2:$H$3001,'Thống kê tháng'!$B$2*100+11))) | N6: =IF(A6="","",IF(B6="Thu",SUMIFS('Sổ giao dịch'!$E$2:$E$3001,'Sổ giao dịch'!$C$2:$C$3001,A6,'Sổ giao dịch'!$H$2:$H$3001,'Thống kê tháng'!$B$2*100+12),SUMIFS('Sổ giao dịch'!$F$2:$F$3001,'Sổ giao dịch'!$C$2:$C$3001,A6,'Sổ giao dịch'!$H$2:$H$3001,'Thống kê tháng'!$B$2*100+12))) | O6: =IF(A6="","",SUM(C6:N6)) | P6: =IF(A6="","",IF('Thống kê tháng'!$B$19=0,0,O6/'Thống kê tháng'!$B$19)) | Q6: =IF(OR(A6="",'Danh mục'!C3=""),"",'Danh mục'!C3) | R6: =IF(OR(Q6="",Q6=0),"",P6/Q6)
A7: =IF('Danh mục'!A4="","",'Danh mục'!A4) | B7: =IF(A7="","",'Danh mục'!B4) | C7: =IF(A7="","",IF(B7="Thu",SUMIFS('Sổ giao dịch'!$E$2:$E$3001,'Sổ giao dịch'!$C$2:$C$3001,A7,'Sổ giao dịch'!$H$2:$H$3001,'Thống kê tháng'!$B$2*100+1),SUMIFS('Sổ giao dịch'!$F$2:$F$3001,'Sổ giao dịch'!$C$2:$C$3001,A7,'Sổ giao dịch'!$H$2:$H$3001,'Thống kê tháng'!$B$2*100+1))) | D7: =IF(A7="","",IF(B7="Thu",SUMIFS('Sổ giao dịch'!$E$2:$E$3001,'Sổ giao dịch'!$C$2:$C$3001,A7,'Sổ giao dịch'!$H$2:$H$3001,'Thống kê tháng'!$B$2*100+2),SUMIFS('Sổ giao dịch'!$F$2:$F$3001,'Sổ giao dịch'!$C$2:$C$3001,A7,'Sổ giao dịch'!$H$2:$H$3001,'Thống kê tháng'!$B$2*100+2))) | E7: =IF(A7="","",IF(B7="Thu",SUMIFS('Sổ giao dịch'!$E$2:$E$3001,'Sổ giao dịch'!$C$2:$C$3001,A7,'Sổ giao dịch'!$H$2:$H$3001,'Thống kê tháng'!$B$2*100+3),SUMIFS('Sổ giao dịch'!$F$2:$F$3001,'Sổ giao dịch'!$C$2:$C$3001,A7,'Sổ giao dịch'!$H$2:$H$3001,'Thống kê tháng'!$B$2*100+3))) | F7: =IF(A7="","",IF(B7="Thu",SUMIFS('Sổ giao dịch'!$E$2:$E$3001,'Sổ giao dịch'!$C$2:$C$3001,A7,'Sổ giao dịch'!$H$2:$H$3001,'Thống kê tháng'!$B$2*100+4),SUMIFS('Sổ giao dịch'!$F$2:$F$3001,'Sổ giao dịch'!$C$2:$C$3001,A7,'Sổ giao dịch'!$H$2:$H$3001,'Thống kê tháng'!$B$2*100+4))) | G7: =IF(A7="","",IF(B7="Thu",SUMIFS('Sổ giao dịch'!$E$2:$E$3001,'Sổ giao dịch'!$C$2:$C$3001,A7,'Sổ giao dịch'!$H$2:$H$3001,'Thống kê tháng'!$B$2*100+5),SUMIFS('Sổ giao dịch'!$F$2:$F$3001,'Sổ giao dịch'!$C$2:$C$3001,A7,'Sổ giao dịch'!$H$2:$H$3001,'Thống kê tháng'!$B$2*100+5))) | H7: =IF(A7="","",IF(B7="Thu",SUMIFS('Sổ giao dịch'!$E$2:$E$3001,'Sổ giao dịch'!$C$2:$C$3001,A7,'Sổ giao dịch'!$H$2:$H$3001,'Thống kê tháng'!$B$2*100+6),SUMIFS('Sổ giao dịch'!$F$2:$F$3001,'Sổ giao dịch'!$C$2:$C$3001,A7,'Sổ giao dịch'!$H$2:$H$3001,'Thống kê tháng'!$B$2*100+6))) | I7: =IF(A7="","",IF(B7="Thu",SUMIFS('Sổ giao dịch'!$E$2:$E$3001,'Sổ giao dịch'!$C$2:$C$3001,A7,'Sổ giao dịch'!$H$2:$H$3001,'Thống kê tháng'!$B$2*100+7),SUMIFS('Sổ giao dịch'!$F$2:$F$3001,'Sổ giao dịch'!$C$2:$C$3001,A7,'Sổ giao dịch'!$H$2:$H$3001,'Thống kê tháng'!$B$2*100+7))) | J7: =IF(A7="","",IF(B7="Thu",SUMIFS('Sổ giao dịch'!$E$2:$E$3001,'Sổ giao dịch'!$C$2:$C$3001,A7,'Sổ giao dịch'!$H$2:$H$3001,'Thống kê tháng'!$B$2*100+8),SUMIFS('Sổ giao dịch'!$F$2:$F$3001,'Sổ giao dịch'!$C$2:$C$3001,A7,'Sổ giao dịch'!$H$2:$H$3001,'Thống kê tháng'!$B$2*100+8))) | K7: =IF(A7="","",IF(B7="Thu",SUMIFS('Sổ giao dịch'!$E$2:$E$3001,'Sổ giao dịch'!$C$2:$C$3001,A7,'Sổ giao dịch'!$H$2:$H$3001,'Thống kê tháng'!$B$2*100+9),SUMIFS('Sổ giao dịch'!$F$2:$F$3001,'Sổ giao dịch'!$C$2:$C$3001,A7,'Sổ giao dịch'!$H$2:$H$3001,'Thống kê tháng'!$B$2*100+9))) | L7: =IF(A7="","",IF(B7="Thu",SUMIFS('Sổ giao dịch'!$E$2:$E$3001,'Sổ giao dịch'!$C$2:$C$3001,A7,'Sổ giao dịch'!$H$2:$H$3001,'Thống kê tháng'!$B$2*100+10),SUMIFS('Sổ giao dịch'!$F$2:$F$3001,'Sổ giao dịch'!$C$2:$C$3001,A7,'Sổ giao dịch'!$H$2:$H$3001,'Thống kê tháng'!$B$2*100+10))) | M7: =IF(A7="","",IF(B7="Thu",SUMIFS('Sổ giao dịch'!$E$2:$E$3001,'Sổ giao dịch'!$C$2:$C$3001,A7,'Sổ giao dịch'!$H$2:$H$3001,'Thống kê tháng'!$B$2*100+11),SUMIFS('Sổ giao dịch'!$F$2:$F$3001,'Sổ giao dịch'!$C$2:$C$3001,A7,'Sổ giao dịch'!$H$2:$H$3001,'Thống kê tháng'!$B$2*100+11))) | N7: =IF(A7="","",IF(B7="Thu",SUMIFS('Sổ giao dịch'!$E$2:$E$3001,'Sổ giao dịch'!$C$2:$C$3001,A7,'Sổ giao dịch'!$H$2:$H$3001,'Thống kê tháng'!$B$2*100+12),SUMIFS('Sổ giao dịch'!$F$2:$F$3001,'Sổ giao dịch'!$C$2:$C$3001,A7,'Sổ giao dịch'!$H$2:$H$3001,'Thống kê tháng'!$B$2*100+12))) | O7: =IF(A7="","",SUM(C7:N7)) | P7: =IF(A7="","",IF('Thống kê tháng'!$B$19=0,0,O7/'Thống kê tháng'!$B$19)) | Q7: =IF(OR(A7="",'Danh mục'!C4=""),"",'Danh mục'!C4) | R7: =IF(OR(Q7="",Q7=0),"",P7/Q7)
A8: =IF('Danh mục'!A5="","",'Danh mục'!A5) | B8: =IF(A8="","",'Danh mục'!B5) | C8: =IF(A8="","",IF(B8="Thu",SUMIFS('Sổ giao dịch'!$E$2:$E$3001,'Sổ giao dịch'!$C$2:$C$3001,A8,'Sổ giao dịch'!$H$2:$H$3001,'Thống kê tháng'!$B$2*100+1),SUMIFS('Sổ giao dịch'!$F$2:$F$3001,'Sổ giao dịch'!$C$2:$C$3001,A8,'Sổ giao dịch'!$H$2:$H$3001,'Thống kê tháng'!$B$2*100+1))) | D8: =IF(A8="","",IF(B8="Thu",SUMIFS('Sổ giao dịch'!$E$2:$E$3001,'Sổ giao dịch'!$C$2:$C$3001,A8,'Sổ giao dịch'!$H$2:$H$3001,'Thống kê tháng'!$B$2*100+2),SUMIFS('Sổ giao dịch'!$F$2:$F$3001,'Sổ giao dịch'!$C$2:$C$3001,A8,'Sổ giao dịch'!$H$2:$H$3001,'Thống kê tháng'!$B$2*100+2))) | E8: =IF(A8="","",IF(B8="Thu",SUMIFS('Sổ giao dịch'!$E$2:$E$3001,'Sổ giao dịch'!$C$2:$C$3001,A8,'Sổ giao dịch'!$H$2:$H$3001,'Thống kê tháng'!$B$2*100+3),SUMIFS('Sổ giao dịch'!$F$2:$F$3001,'Sổ giao dịch'!$C$2:$C$3001,A8,'Sổ giao dịch'!$H$2:$H$3001,'Thống kê tháng'!$B$2*100+3))) | F8: =IF(A8="","",IF(B8="Thu",SUMIFS('Sổ giao dịch'!$E$2:$E$3001,'Sổ giao dịch'!$C$2:$C$3001,A8,'Sổ giao dịch'!$H$2:$H$3001,'Thống kê tháng'!$B$2*100+4),SUMIFS('Sổ giao dịch'!$F$2:$F$3001,'Sổ giao dịch'!$C$2:$C$3001,A8,'Sổ giao dịch'!$H$2:$H$3001,'Thống kê tháng'!$B$2*100+4))) | G8: =IF(A8="","",IF(B8="Thu",SUMIFS('Sổ giao dịch'!$E$2:$E$3001,'Sổ giao dịch'!$C$2:$C$3001,A8,'Sổ giao dịch'!$H$2:$H$3001,'Thống kê tháng'!$B$2*100+5),SUMIFS('Sổ giao dịch'!$F$2:$F$3001,'Sổ giao dịch'!$C$2:$C$3001,A8,'Sổ giao dịch'!$H$2:$H$3001,'Thống kê tháng'!$B$2*100+5))) | H8: =IF(A8="","",IF(B8="Thu",SUMIFS('Sổ giao dịch'!$E$2:$E$3001,'Sổ giao dịch'!$C$2:$C$3001,A8,'Sổ giao dịch'!$H$2:$H$3001,'Thống kê tháng'!$B$2*100+6),SUMIFS('Sổ giao dịch'!$F$2:$F$3001,'Sổ giao dịch'!$C$2:$C$3001,A8,'Sổ giao dịch'!$H$2:$H$3001,'Thống kê tháng'!$B$2*100+6))) | I8: =IF(A8="","",IF(B8="Thu",SUMIFS('Sổ giao dịch'!$E$2:$E$3001,'Sổ giao dịch'!$C$2:$C$3001,A8,'Sổ giao dịch'!$H$2:$H$3001,'Thống kê tháng'!$B$2*100+7),SUMIFS('Sổ giao dịch'!$F$2:$F$3001,'Sổ giao dịch'!$C$2:$C$3001,A8,'Sổ giao dịch'!$H$2:$H$3001,'Thống kê tháng'!$B$2*100+7))) | J8: =IF(A8="","",IF(B8="Thu",SUMIFS('Sổ giao dịch'!$E$2:$E$3001,'Sổ giao dịch'!$C$2:$C$3001,A8,'Sổ giao dịch'!$H$2:$H$3001,'Thống kê tháng'!$B$2*100+8),SUMIFS('Sổ giao dịch'!$F$2:$F$3001,'Sổ giao dịch'!$C$2:$C$3001,A8,'Sổ giao dịch'!$H$2:$H$3001,'Thống kê tháng'!$B$2*100+8))) | K8: =IF(A8="","",IF(B8="Thu",SUMIFS('Sổ giao dịch'!$E$2:$E$3001,'Sổ giao dịch'!$C$2:$C$3001,A8,'Sổ giao dịch'!$H$2:$H$3001,'Thống kê tháng'!$B$2*100+9),SUMIFS('Sổ giao dịch'!$F$2:$F$3001,'Sổ giao dịch'!$C$2:$C$3001,A8,'Sổ giao dịch'!$H$2:$H$3001,'Thống kê tháng'!$B$2*100+9))) | L8: =IF(A8="","",IF(B8="Thu",SUMIFS('Sổ giao dịch'!$E$2:$E$3001,'Sổ giao dịch'!$C$2:$C$3001,A8,'Sổ giao dịch'!$H$2:$H$3001,'Thống kê tháng'!$B$2*100+10),SUMIFS('Sổ giao dịch'!$F$2:$F$3001,'Sổ giao dịch'!$C$2:$C$3001,A8,'Sổ giao dịch'!$H$2:$H$3001,'Thống kê tháng'!$B$2*100+10))) | M8: =IF(A8="","",IF(B8="Thu",SUMIFS('Sổ giao dịch'!$E$2:$E$3001,'Sổ giao dịch'!$C$2:$C$3001,A8,'Sổ giao dịch'!$H$2:$H$3001,'Thống kê tháng'!$B$2*100+11),SUMIFS('Sổ giao dịch'!$F$2:$F$3001,'Sổ giao dịch'!$C$2:$C$3001,A8,'Sổ giao dịch'!$H$2:$H$3001,'Thống kê tháng'!$B$2*100+11))) | N8: =IF(A8="","",IF(B8="Thu",SUMIFS('Sổ giao dịch'!$E$2:$E$3001,'Sổ giao dịch'!$C$2:$C$3001,A8,'Sổ giao dịch'!$H$2:$H$3001,'Thống kê tháng'!$B$2*100+12),SUMIFS('Sổ giao dịch'!$F$2:$F$3001,'Sổ giao dịch'!$C$2:$C$3001,A8,'Sổ giao dịch'!$H$2:$H$3001,'Thống kê tháng'!$B$2*100+12))) | O8: =IF(A8="","",SUM(C8:N8)) | P8: =IF(A8="","",IF('Thống kê tháng'!$B$19=0,0,O8/'Thống kê tháng'!$B$19)) | Q8: =IF(OR(A8="",'Danh mục'!C5=""),"",'Danh mục'!C5) | R8: =IF(OR(Q8="",Q8=0),"",P8/Q8)
A9: =IF('Danh mục'!A6="","",'Danh mục'!A6) | B9: =IF(A9="","",'Danh mục'!B6) | C9: =IF(A9="","",IF(B9="Thu",SUMIFS('Sổ giao dịch'!$E$2:$E$3001,'Sổ giao dịch'!$C$2:$C$3001,A9,'Sổ giao dịch'!$H$2:$H$3001,'Thống kê tháng'!$B$2*100+1),SUMIFS('Sổ giao dịch'!$F$2:$F$3001,'Sổ giao dịch'!$C$2:$C$3001,A9,'Sổ giao dịch'!$H$2:$H$3001,'Thống kê tháng'!$B$2*100+1))) | D9: =IF(A9="","",IF(B9="Thu",SUMIFS('Sổ giao dịch'!$E$2:$E$3001,'Sổ giao dịch'!$C$2:$C$3001,A9,'Sổ giao dịch'!$H$2:$H$3001,'Thống kê tháng'!$B$2*100+2),SUMIFS('Sổ giao dịch'!$F$2:$F$3001,'Sổ giao dịch'!$C$2:$C$3001,A9,'Sổ giao dịch'!$H$2:$H$3001,'Thống kê tháng'!$B$2*100+2))) | E9: =IF(A9="","",IF(B9="Thu",SUMIFS('Sổ giao dịch'!$E$2:$E$3001,'Sổ giao dịch'!$C$2:$C$3001,A9,'Sổ giao dịch'!$H$2:$H$3001,'Thống kê tháng'!$B$2*100+3),SUMIFS('Sổ giao dịch'!$F$2:$F$3001,'Sổ giao dịch'!$C$2:$C$3001,A9,'Sổ giao dịch'!$H$2:$H$3001,'Thống kê tháng'!$B$2*100+3))) | F9: =IF(A9="","",IF(B9="Thu",SUMIFS('Sổ giao dịch'!$E$2:$E$3001,'Sổ giao dịch'!$C$2:$C$3001,A9,'Sổ giao dịch'!$H$2:$H$3001,'Thống kê tháng'!$B$2*100+4),SUMIFS('Sổ giao dịch'!$F$2:$F$3001,'Sổ giao dịch'!$C$2:$C$3001,A9,'Sổ giao dịch'!$H$2:$H$3001,'Thống kê tháng'!$B$2*100+4))) | G9: =IF(A9="","",IF(B9="Thu",SUMIFS('Sổ giao dịch'!$E$2:$E$3001,'Sổ giao dịch'!$C$2:$C$3001,A9,'Sổ giao dịch'!$H$2:$H$3001,'Thống kê tháng'!$B$2*100+5),SUMIFS('Sổ giao dịch'!$F$2:$F$3001,'Sổ giao dịch'!$C$2:$C$3001,A9,'Sổ giao dịch'!$H$2:$H$3001,'Thống kê tháng'!$B$2*100+5))) | H9: =IF(A9="","",IF(B9="Thu",SUMIFS('Sổ giao dịch'!$E$2:$E$3001,'Sổ giao dịch'!$C$2:$C$3001,A9,'Sổ giao dịch'!$H$2:$H$3001,'Thống kê tháng'!$B$2*100+6),SUMIFS('Sổ giao dịch'!$F$2:$F$3001,'Sổ giao dịch'!$C$2:$C$3001,A9,'Sổ giao dịch'!$H$2:$H$3001,'Thống kê tháng'!$B$2*100+6))) | I9: =IF(A9="","",IF(B9="Thu",SUMIFS('Sổ giao dịch'!$E$2:$E$3001,'Sổ giao dịch'!$C$2:$C$3001,A9,'Sổ giao dịch'!$H$2:$H$3001,'Thống kê tháng'!$B$2*100+7),SUMIFS('Sổ giao dịch'!$F$2:$F$3001,'Sổ giao dịch'!$C$2:$C$3001,A9,'Sổ giao dịch'!$H$2:$H$3001,'Thống kê tháng'!$B$2*100+7))) | J9: =IF(A9="","",IF(B9="Thu",SUMIFS('Sổ giao dịch'!$E$2:$E$3001,'Sổ giao dịch'!$C$2:$C$3001,A9,'Sổ giao dịch'!$H$2:$H$3001,'Thống kê tháng'!$B$2*100+8),SUMIFS('Sổ giao dịch'!$F$2:$F$3001,'Sổ giao dịch'!$C$2:$C$3001,A9,'Sổ giao dịch'!$H$2:$H$3001,'Thống kê tháng'!$B$2*100+8))) | K9: =IF(A9="","",IF(B9="Thu",SUMIFS('Sổ giao dịch'!$E$2:$E$3001,'Sổ giao dịch'!$C$2:$C$3001,A9,'Sổ giao dịch'!$H$2:$H$3001,'Thống kê tháng'!$B$2*100+9),SUMIFS('Sổ giao dịch'!$F$2:$F$3001,'Sổ giao dịch'!$C$2:$C$3001,A9,'Sổ giao dịch'!$H$2:$H$3001,'Thống kê tháng'!$B$2*100+9))) | L9: =IF(A9="","",IF(B9="Thu",SUMIFS('Sổ giao dịch'!$E$2:$E$3001,'Sổ giao dịch'!$C$2:$C$3001,A9,'Sổ giao dịch'!$H$2:$H$3001,'Thống kê tháng'!$B$2*100+10),SUMIFS('Sổ giao dịch'!$F$2:$F$3001,'Sổ giao dịch'!$C$2:$C$3001,A9,'Sổ giao dịch'!$H$2:$H$3001,'Thống kê tháng'!$B$2*100+10))) | M9: =IF(A9="","",IF(B9="Thu",SUMIFS('Sổ giao dịch'!$E$2:$E$3001,'Sổ giao dịch'!$C$2:$C$3001,A9,'Sổ giao dịch'!$H$2:$H$3001,'Thống kê tháng'!$B$2*100+11),SUMIFS('Sổ giao dịch'!$F$2:$F$3001,'Sổ giao dịch'!$C$2:$C$3001,A9,'Sổ giao dịch'!$H$2:$H$3001,'Thống kê tháng'!$B$2*100+11))) | N9: =IF(A9="","",IF(B9="Thu",SUMIFS('Sổ giao dịch'!$E$2:$E$3001,'Sổ giao dịch'!$C$2:$C$3001,A9,'Sổ giao dịch'!$H$2:$H$3001,'Thống kê tháng'!$B$2*100+12),SUMIFS('Sổ giao dịch'!$F$2:$F$3001,'Sổ giao dịch'!$C$2:$C$3001,A9,'Sổ giao dịch'!$H$2:$H$3001,'Thống kê tháng'!$B$2*100+12))) | O9: =IF(A9="","",SUM(C9:N9)) | P9: =IF(A9="","",IF('Thống kê tháng'!$B$19=0,0,O9/'Thống kê tháng'!$B$19)) | Q9: =IF(OR(A9="",'Danh mục'!C6=""),"",'Danh mục'!C6) | R9: =IF(OR(Q9="",Q9=0),"",P9/Q9)
A10: =IF('Danh mục'!A7="","",'Danh mục'!A7) | B10: =IF(A10="","",'Danh mục'!B7) | C10: =IF(A10="","",IF(B10="Thu",SUMIFS('Sổ giao dịch'!$E$2:$E$3001,'Sổ giao dịch'!$C$2:$C$3001,A10,'Sổ giao dịch'!$H$2:$H$3001,'Thống kê tháng'!$B$2*100+1),SUMIFS('Sổ giao dịch'!$F$2:$F$3001,'Sổ giao dịch'!$C$2:$C$3001,A10,'Sổ giao dịch'!$H$2:$H$3001,'Thống kê tháng'!$B$2*100+1))) | D10: =IF(A10="","",IF(B10="Thu",SUMIFS('Sổ giao dịch'!$E$2:$E$3001,'Sổ giao dịch'!$C$2:$C$3001,A10,'Sổ giao dịch'!$H$2:$H$3001,'Thống kê tháng'!$B$2*100+2),SUMIFS('Sổ giao dịch'!$F$2:$F$3001,'Sổ giao dịch'!$C$2:$C$3001,A10,'Sổ giao dịch'!$H$2:$H$3001,'Thống kê tháng'!$B$2*100+2))) | E10: =IF(A10="","",IF(B10="Thu",SUMIFS('Sổ giao dịch'!$E$2:$E$3001,'Sổ giao dịch'!$C$2:$C$3001,A10,'Sổ giao dịch'!$H$2:$H$3001,'Thống kê tháng'!$B$2*100+3),SUMIFS('Sổ giao dịch'!$F$2:$F$3001,'Sổ giao dịch'!$C$2:$C$3001,A10,'Sổ giao dịch'!$H$2:$H$3001,'Thống kê tháng'!$B$2*100+3))) | F10: =IF(A10="","",IF(B10="Thu",SUMIFS('Sổ giao dịch'!$E$2:$E$3001,'Sổ giao dịch'!$C$2:$C$3001,A10,'Sổ giao dịch'!$H$2:$H$3001,'Thống kê tháng'!$B$2*100+4),SUMIFS('Sổ giao dịch'!$F$2:$F$3001,'Sổ giao dịch'!$C$2:$C$3001,A10,'Sổ giao dịch'!$H$2:$H$3001,'Thống kê tháng'!$B$2*100+4))) | G10: =IF(A10="","",IF(B10="Thu",SUMIFS('Sổ giao dịch'!$E$2:$E$3001,'Sổ giao dịch'!$C$2:$C$3001,A10,'Sổ giao dịch'!$H$2:$H$3001,'Thống kê tháng'!$B$2*100+5),SUMIFS('Sổ giao dịch'!$F$2:$F$3001,'Sổ giao dịch'!$C$2:$C$3001,A10,'Sổ giao dịch'!$H$2:$H$3001,'Thống kê tháng'!$B$2*100+5))) | H10: =IF(A10="","",IF(B10="Thu",SUMIFS('Sổ giao dịch'!$E$2:$E$3001,'Sổ giao dịch'!$C$2:$C$3001,A10,'Sổ giao dịch'!$H$2:$H$3001,'Thống kê tháng'!$B$2*100+6),SUMIFS('Sổ giao dịch'!$F$2:$F$3001,'Sổ giao dịch'!$C$2:$C$3001,A10,'Sổ giao dịch'!$H$2:$H$3001,'Thống kê tháng'!$B$2*100+6))) | I10: =IF(A10="","",IF(B10="Thu",SUMIFS('Sổ giao dịch'!$E$2:$E$3001,'Sổ giao dịch'!$C$2:$C$3001,A10,'Sổ giao dịch'!$H$2:$H$3001,'Thống kê tháng'!$B$2*100+7),SUMIFS('Sổ giao dịch'!$F$2:$F$3001,'Sổ giao dịch'!$C$2:$C$3001,A10,'Sổ giao dịch'!$H$2:$H$3001,'Thống kê tháng'!$B$2*100+7))) | J10: =IF(A10="","",IF(B10="Thu",SUMIFS('Sổ giao dịch'!$E$2:$E$3001,'Sổ giao dịch'!$C$2:$C$3001,A10,'Sổ giao dịch'!$H$2:$H$3001,'Thống kê tháng'!$B$2*100+8),SUMIFS('Sổ giao dịch'!$F$2:$F$3001,'Sổ giao dịch'!$C$2:$C$3001,A10,'Sổ giao dịch'!$H$2:$H$3001,'Thống kê tháng'!$B$2*100+8))) | K10: =IF(A10="","",IF(B10="Thu",SUMIFS('Sổ giao dịch'!$E$2:$E$3001,'Sổ giao dịch'!$C$2:$C$3001,A10,'Sổ giao dịch'!$H$2:$H$3001,'Thống kê tháng'!$B$2*100+9),SUMIFS('Sổ giao dịch'!$F$2:$F$3001,'Sổ giao dịch'!$C$2:$C$3001,A10,'Sổ giao dịch'!$H$2:$H$3001,'Thống kê tháng'!$B$2*100+9))) | L10: =IF(A10="","",IF(B10="Thu",SUMIFS('Sổ giao dịch'!$E$2:$E$3001,'Sổ giao dịch'!$C$2:$C$3001,A10,'Sổ giao dịch'!$H$2:$H$3001,'Thống kê tháng'!$B$2*100+10),SUMIFS('Sổ giao dịch'!$F$2:$F$3001,'Sổ giao dịch'!$C$2:$C$3001,A10,'Sổ giao dịch'!$H$2:$H$3001,'Thống kê tháng'!$B$2*100+10))) | M10: =IF(A10="","",IF(B10="Thu",SUMIFS('Sổ giao dịch'!$E$2:$E$3001,'Sổ giao dịch'!$C$2:$C$3001,A10,'Sổ giao dịch'!$H$2:$H$3001,'Thống kê tháng'!$B$2*100+11),SUMIFS('Sổ giao dịch'!$F$2:$F$3001,'Sổ giao dịch'!$C$2:$C$3001,A10,'Sổ giao dịch'!$H$2:$H$3001,'Thống kê tháng'!$B$2*100+11))) | N10: =IF(A10="","",IF(B10="Thu",SUMIFS('Sổ giao dịch'!$E$2:$E$3001,'Sổ giao dịch'!$C$2:$C$3001,A10,'Sổ giao dịch'!$H$2:$H$3001,'Thống kê tháng'!$B$2*100+12),SUMIFS('Sổ giao dịch'!$F$2:$F$3001,'Sổ giao dịch'!$C$2:$C$3001,A10,'Sổ giao dịch'!$H$2:$H$3001,'Thống kê tháng'!$B$2*100+12))) | O10: =IF(A10="","",SUM(C10:N10)) | P10: =IF(A10="","",IF('Thống kê tháng'!$B$19=0,0,O10/'Thống kê tháng'!$B$19)) | Q10: =IF(OR(A10="",'Danh mục'!C7=""),"",'Danh mục'!C7) | R10: =IF(OR(Q10="",Q10=0),"",P10/Q10)
A11: =IF('Danh mục'!A8="","",'Danh mục'!A8) | B11: =IF(A11="","",'Danh mục'!B8) | C11: =IF(A11="","",IF(B11="Thu",SUMIFS('Sổ giao dịch'!$E$2:$E$3001,'Sổ giao dịch'!$C$2:$C$3001,A11,'Sổ giao dịch'!$H$2:$H$3001,'Thống kê tháng'!$B$2*100+1),SUMIFS('Sổ giao dịch'!$F$2:$F$3001,'Sổ giao dịch'!$C$2:$C$3001,A11,'Sổ giao dịch'!$H$2:$H$3001,'Thống kê tháng'!$B$2*100+1))) | D11: =IF(A11="","",IF(B11="Thu",SUMIFS('Sổ giao dịch'!$E$2:$E$3001,'Sổ giao dịch'!$C$2:$C$3001,A11,'Sổ giao dịch'!$H$2:$H$3001,'Thống kê tháng'!$B$2*100+2),SUMIFS('Sổ giao dịch'!$F$2:$F$3001,'Sổ giao dịch'!$C$2:$C$3001,A11,'Sổ giao dịch'!$H$2:$H$3001,'Thống kê tháng'!$B$2*100+2))) | E11: =IF(A11="","",IF(B11="Thu",SUMIFS('Sổ giao dịch'!$E$2:$E$3001,'Sổ giao dịch'!$C$2:$C$3001,A11,'Sổ giao dịch'!$H$2:$H$3001,'Thống kê tháng'!$B$2*100+3),SUMIFS('Sổ giao dịch'!$F$2:$F$3001,'Sổ giao dịch'!$C$2:$C$3001,A11,'Sổ giao dịch'!$H$2:$H$3001,'Thống kê tháng'!$B$2*100+3))) | F11: =IF(A11="","",IF(B11="Thu",SUMIFS('Sổ giao dịch'!$E$2:$E$3001,'Sổ giao dịch'!$C$2:$C$3001,A11,'Sổ giao dịch'!$H$2:$H$3001,'Thống kê tháng'!$B$2*100+4),SUMIFS('Sổ giao dịch'!$F$2:$F$3001,'Sổ giao dịch'!$C$2:$C$3001,A11,'Sổ giao dịch'!$H$2:$H$3001,'Thống kê tháng'!$B$2*100+4))) | G11: =IF(A11="","",IF(B11="Thu",SUMIFS('Sổ giao dịch'!$E$2:$E$3001,'Sổ giao dịch'!$C$2:$C$3001,A11,'Sổ giao dịch'!$H$2:$H$3001,'Thống kê tháng'!$B$2*100+5),SUMIFS('Sổ giao dịch'!$F$2:$F$3001,'Sổ giao dịch'!$C$2:$C$3001,A11,'Sổ giao dịch'!$H$2:$H$3001,'Thống kê tháng'!$B$2*100+5))) | H11: =IF(A11="","",IF(B11="Thu",SUMIFS('Sổ giao dịch'!$E$2:$E$3001,'Sổ giao dịch'!$C$2:$C$3001,A11,'Sổ giao dịch'!$H$2:$H$3001,'Thống kê tháng'!$B$2*100+6),SUMIFS('Sổ giao dịch'!$F$2:$F$3001,'Sổ giao dịch'!$C$2:$C$3001,A11,'Sổ giao dịch'!$H$2:$H$3001,'Thống kê tháng'!$B$2*100+6))) | I11: =IF(A11="","",IF(B11="Thu",SUMIFS('Sổ giao dịch'!$E$2:$E$3001,'Sổ giao dịch'!$C$2:$C$3001,A11,'Sổ giao dịch'!$H$2:$H$3001,'Thống kê tháng'!$B$2*100+7),SUMIFS('Sổ giao dịch'!$F$2:$F$3001,'Sổ giao dịch'!$C$2:$C$3001,A11,'Sổ giao dịch'!$H$2:$H$3001,'Thống kê tháng'!$B$2*100+7))) | J11: =IF(A11="","",IF(B11="Thu",SUMIFS('Sổ giao dịch'!$E$2:$E$3001,'Sổ giao dịch'!$C$2:$C$3001,A11,'Sổ giao dịch'!$H$2:$H$3001,'Thống kê tháng'!$B$2*100+8),SUMIFS('Sổ giao dịch'!$F$2:$F$3001,'Sổ giao dịch'!$C$2:$C$3001,A11,'Sổ giao dịch'!$H$2:$H$3001,'Thống kê tháng'!$B$2*100+8))) | K11: =IF(A11="","",IF(B11="Thu",SUMIFS('Sổ giao dịch'!$E$2:$E$3001,'Sổ giao dịch'!$C$2:$C$3001,A11,'Sổ giao dịch'!$H$2:$H$3001,'Thống kê tháng'!$B$2*100+9),SUMIFS('Sổ giao dịch'!$F$2:$F$3001,'Sổ giao dịch'!$C$2:$C$3001,A11,'Sổ giao dịch'!$H$2:$H$3001,'Thống kê tháng'!$B$2*100+9))) | L11: =IF(A11="","",IF(B11="Thu",SUMIFS('Sổ giao dịch'!$E$2:$E$3001,'Sổ giao dịch'!$C$2:$C$3001,A11,'Sổ giao dịch'!$H$2:$H$3001,'Thống kê tháng'!$B$2*100+10),SUMIFS('Sổ giao dịch'!$F$2:$F$3001,'Sổ giao dịch'!$C$2:$C$3001,A11,'Sổ giao dịch'!$H$2:$H$3001,'Thống kê tháng'!$B$2*100+10))) | M11: =IF(A11="","",IF(B11="Thu",SUMIFS('Sổ giao dịch'!$E$2:$E$3001,'Sổ giao dịch'!$C$2:$C$3001,A11,'Sổ giao dịch'!$H$2:$H$3001,'Thống kê tháng'!$B$2*100+11),SUMIFS('Sổ giao dịch'!$F$2:$F$3001,'Sổ giao dịch'!$C$2:$C$3001,A11,'Sổ giao dịch'!$H$2:$H$3001,'Thống kê tháng'!$B$2*100+11))) | N11: =IF(A11="","",IF(B11="Thu",SUMIFS('Sổ giao dịch'!$E$2:$E$3001,'Sổ giao dịch'!$C$2:$C$3001,A11,'Sổ giao dịch'!$H$2:$H$3001,'Thống kê tháng'!$B$2*100+12),SUMIFS('Sổ giao dịch'!$F$2:$F$3001,'Sổ giao dịch'!$C$2:$C$3001,A11,'Sổ giao dịch'!$H$2:$H$3001,'Thống kê tháng'!$B$2*100+12))) | O11: =IF(A11="","",SUM(C11:N11)) | P11: =IF(A11="","",IF('Thống kê tháng'!$B$19=0,0,O11/'Thống kê tháng'!$B$19)) | Q11: =IF(OR(A11="",'Danh mục'!C8=""),"",'Danh mục'!C8) | R11: =IF(OR(Q11="",Q11=0),"",P11/Q11)
A12: =IF('Danh mục'!A9="","",'Danh mục'!A9) | B12: =IF(A12="","",'Danh mục'!B9) | C12: =IF(A12="","",IF(B12="Thu",SUMIFS('Sổ giao dịch'!$E$2:$E$3001,'Sổ giao dịch'!$C$2:$C$3001,A12,'Sổ giao dịch'!$H$2:$H$3001,'Thống kê tháng'!$B$2*100+1),SUMIFS('Sổ giao dịch'!$F$2:$F$3001,'Sổ giao dịch'!$C$2:$C$3001,A12,'Sổ giao dịch'!$H$2:$H$3001,'Thống kê tháng'!$B$2*100+1))) | D12: =IF(A12="","",IF(B12="Thu",SUMIFS('Sổ giao dịch'!$E$2:$E$3001,'Sổ giao dịch'!$C$2:$C$3001,A12,'Sổ giao dịch'!$H$2:$H$3001,'Thống kê tháng'!$B$2*100+2),SUMIFS('Sổ giao dịch'!$F$2:$F$3001,'Sổ giao dịch'!$C$2:$C$3001,A12,'Sổ giao dịch'!$H$2:$H$3001,'Thống kê tháng'!$B$2*100+2))) | E12: =IF(A12="","",IF(B12="Thu",SUMIFS('Sổ giao dịch'!$E$2:$E$3001,'Sổ giao dịch'!$C$2:$C$3001,A12,'Sổ giao dịch'!$H$2:$H$3001,'Thống kê tháng'!$B$2*100+3),SUMIFS('Sổ giao dịch'!$F$2:$F$3001,'Sổ giao dịch'!$C$2:$C$3001,A12,'Sổ giao dịch'!$H$2:$H$3001,'Thống kê tháng'!$B$2*100+3))) | F12: =IF(A12="","",IF(B12="Thu",SUMIFS('Sổ giao dịch'!$E$2:$E$3001,'Sổ giao dịch'!$C$2:$C$3001,A12,'Sổ giao dịch'!$H$2:$H$3001,'Thống kê tháng'!$B$2*100+4),SUMIFS('Sổ giao dịch'!$F$2:$F$3001,'Sổ giao dịch'!$C$2:$C$3001,A12,'Sổ giao dịch'!$H$2:$H$3001,'Thống kê tháng'!$B$2*100+4))) | G12: =IF(A12="","",IF(B12="Thu",SUMIFS('Sổ giao dịch'!$E$2:$E$3001,'Sổ giao dịch'!$C$2:$C$3001,A12,'Sổ giao dịch'!$H$2:$H$3001,'Thống kê tháng'!$B$2*100+5),SUMIFS('Sổ giao dịch'!$F$2:$F$3001,'Sổ giao dịch'!$C$2:$C$3001,A12,'Sổ giao dịch'!$H$2:$H$3001,'Thống kê tháng'!$B$2*100+5))) | H12: =IF(A12="","",IF(B12="Thu",SUMIFS('Sổ giao dịch'!$E$2:$E$3001,'Sổ giao dịch'!$C$2:$C$3001,A12,'Sổ giao dịch'!$H$2:$H$3001,'Thống kê tháng'!$B$2*100+6),SUMIFS('Sổ giao dịch'!$F$2:$F$3001,'Sổ giao dịch'!$C$2:$C$3001,A12,'Sổ giao dịch'!$H$2:$H$3001,'Thống kê tháng'!$B$2*100+6))) | I12: =IF(A12="","",IF(B12="Thu",SUMIFS('Sổ giao dịch'!$E$2:$E$3001,'Sổ giao dịch'!$C$2:$C$3001,A12,'Sổ giao dịch'!$H$2:$H$3001,'Thống kê tháng'!$B$2*100+7),SUMIFS('Sổ giao dịch'!$F$2:$F$3001,'Sổ giao dịch'!$C$2:$C$3001,A12,'Sổ giao dịch'!$H$2:$H$3001,'Thống kê tháng'!$B$2*100+7))) | J12: =IF(A12="","",IF(B12="Thu",SUMIFS('Sổ giao dịch'!$E$2:$E$3001,'Sổ giao dịch'!$C$2:$C$3001,A12,'Sổ giao dịch'!$H$2:$H$3001,'Thống kê tháng'!$B$2*100+8),SUMIFS('Sổ giao dịch'!$F$2:$F$3001,'Sổ giao dịch'!$C$2:$C$3001,A12,'Sổ giao dịch'!$H$2:$H$3001,'Thống kê tháng'!$B$2*100+8))) | K12: =IF(A12="","",IF(B12="Thu",SUMIFS('Sổ giao dịch'!$E$2:$E$3001,'Sổ giao dịch'!$C$2:$C$3001,A12,'Sổ giao dịch'!$H$2:$H$3001,'Thống kê tháng'!$B$2*100+9),SUMIFS('Sổ giao dịch'!$F$2:$F$3001,'Sổ giao dịch'!$C$2:$C$3001,A12,'Sổ giao dịch'!$H$2:$H$3001,'Thống kê tháng'!$B$2*100+9))) | L12: =IF(A12="","",IF(B12="Thu",SUMIFS('Sổ giao dịch'!$E$2:$E$3001,'Sổ giao dịch'!$C$2:$C$3001,A12,'Sổ giao dịch'!$H$2:$H$3001,'Thống kê tháng'!$B$2*100+10),SUMIFS('Sổ giao dịch'!$F$2:$F$3001,'Sổ giao dịch'!$C$2:$C$3001,A12,'Sổ giao dịch'!$H$2:$H$3001,'Thống kê tháng'!$B$2*100+10))) | M12: =IF(A12="","",IF(B12="Thu",SUMIFS('Sổ giao dịch'!$E$2:$E$3001,'Sổ giao dịch'!$C$2:$C$3001,A12,'Sổ giao dịch'!$H$2:$H$3001,'Thống kê tháng'!$B$2*100+11),SUMIFS('Sổ giao dịch'!$F$2:$F$3001,'Sổ giao dịch'!$C$2:$C$3001,A12,'Sổ giao dịch'!$H$2:$H$3001,'Thống kê tháng'!$B$2*100+11))) | N12: =IF(A12="","",IF(B12="Thu",SUMIFS('Sổ giao dịch'!$E$2:$E$3001,'Sổ giao dịch'!$C$2:$C$3001,A12,'Sổ giao dịch'!$H$2:$H$3001,'Thống kê tháng'!$B$2*100+12),SUMIFS('Sổ giao dịch'!$F$2:$F$3001,'Sổ giao dịch'!$C$2:$C$3001,A12,'Sổ giao dịch'!$H$2:$H$3001,'Thống kê tháng'!$B$2*100+12))) | O12: =IF(A12="","",SUM(C12:N12)) | P12: =IF(A12="","",IF('Thống kê tháng'!$B$19=0,0,O12/'Thống kê tháng'!$B$19)) | Q12: =IF(OR(A12="",'Danh mục'!C9=""),"",'Danh mục'!C9) | R12: =IF(OR(Q12="",Q12=0),"",P12/Q12)
A13: =IF('Danh mục'!A10="","",'Danh mục'!A10) | B13: =IF(A13="","",'Danh mục'!B10) | C13: =IF(A13="","",IF(B13="Thu",SUMIFS('Sổ giao dịch'!$E$2:$E$3001,'Sổ giao dịch'!$C$2:$C$3001,A13,'Sổ giao dịch'!$H$2:$H$3001,'Thống kê tháng'!$B$2*100+1),SUMIFS('Sổ giao dịch'!$F$2:$F$3001,'Sổ giao dịch'!$C$2:$C$3001,A13,'Sổ giao dịch'!$H$2:$H$3001,'Thống kê tháng'!$B$2*100+1))) | D13: =IF(A13="","",IF(B13="Thu",SUMIFS('Sổ giao dịch'!$E$2:$E$3001,'Sổ giao dịch'!$C$2:$C$3001,A13,'Sổ giao dịch'!$H$2:$H$3001,'Thống kê tháng'!$B$2*100+2),SUMIFS('Sổ giao dịch'!$F$2:$F$3001,'Sổ giao dịch'!$C$2:$C$3001,A13,'Sổ giao dịch'!$H$2:$H$3001,'Thống kê tháng'!$B$2*100+2))) | E13: =IF(A13="","",IF(B13="Thu",SUMIFS('Sổ giao dịch'!$E$2:$E$3001,'Sổ giao dịch'!$C$2:$C$3001,A13,'Sổ giao dịch'!$H$2:$H$3001,'Thống kê tháng'!$B$2*100+3),SUMIFS('Sổ giao dịch'!$F$2:$F$3001,'Sổ giao dịch'!$C$2:$C$3001,A13,'Sổ giao dịch'!$H$2:$H$3001,'Thống kê tháng'!$B$2*100+3))) | F13: =IF(A13="","",IF(B13="Thu",SUMIFS('Sổ giao dịch'!$E$2:$E$3001,'Sổ giao dịch'!$C$2:$C$3001,A13,'Sổ giao dịch'!$H$2:$H$3001,'Thống kê tháng'!$B$2*100+4),SUMIFS('Sổ giao dịch'!$F$2:$F$3001,'Sổ giao dịch'!$C$2:$C$3001,A13,'Sổ giao dịch'!$H$2:$H$3001,'Thống kê tháng'!$B$2*100+4))) | G13: =IF(A13="","",IF(B13="Thu",SUMIFS('Sổ giao dịch'!$E$2:$E$3001,'Sổ giao dịch'!$C$2:$C$3001,A13,'Sổ giao dịch'!$H$2:$H$3001,'Thống kê tháng'!$B$2*100+5),SUMIFS('Sổ giao dịch'!$F$2:$F$3001,'Sổ giao dịch'!$C$2:$C$3001,A13,'Sổ giao dịch'!$H$2:$H$3001,'Thống kê tháng'!$B$2*100+5))) | H13: =IF(A13="","",IF(B13="Thu",SUMIFS('Sổ giao dịch'!$E$2:$E$3001,'Sổ giao dịch'!$C$2:$C$3001,A13,'Sổ giao dịch'!$H$2:$H$3001,'Thống kê tháng'!$B$2*100+6),SUMIFS('Sổ giao dịch'!$F$2:$F$3001,'Sổ giao dịch'!$C$2:$C$3001,A13,'Sổ giao dịch'!$H$2:$H$3001,'Thống kê tháng'!$B$2*100+6))) | I13: =IF(A13="","",IF(B13="Thu",SUMIFS('Sổ giao dịch'!$E$2:$E$3001,'Sổ giao dịch'!$C$2:$C$3001,A13,'Sổ giao dịch'!$H$2:$H$3001,'Thống kê tháng'!$B$2*100+7),SUMIFS('Sổ giao dịch'!$F$2:$F$3001,'Sổ giao dịch'!$C$2:$C$3001,A13,'Sổ giao dịch'!$H$2:$H$3001,'Thống kê tháng'!$B$2*100+7))) | J13: =IF(A13="","",IF(B13="Thu",SUMIFS('Sổ giao dịch'!$E$2:$E$3001,'Sổ giao dịch'!$C$2:$C$3001,A13,'Sổ giao dịch'!$H$2:$H$3001,'Thống kê tháng'!$B$2*100+8),SUMIFS('Sổ giao dịch'!$F$2:$F$3001,'Sổ giao dịch'!$C$2:$C$3001,A13,'Sổ giao dịch'!$H$2:$H$3001,'Thống kê tháng'!$B$2*100+8))) | K13: =IF(A13="","",IF(B13="Thu",SUMIFS('Sổ giao dịch'!$E$2:$E$3001,'Sổ giao dịch'!$C$2:$C$3001,A13,'Sổ giao dịch'!$H$2:$H$3001,'Thống kê tháng'!$B$2*100+9),SUMIFS('Sổ giao dịch'!$F$2:$F$3001,'Sổ giao dịch'!$C$2:$C$3001,A13,'Sổ giao dịch'!$H$2:$H$3001,'Thống kê tháng'!$B$2*100+9))) | L13: =IF(A13="","",IF(B13="Thu",SUMIFS('Sổ giao dịch'!$E$2:$E$3001,'Sổ giao dịch'!$C$2:$C$3001,A13,'Sổ giao dịch'!$H$2:$H$3001,'Thống kê tháng'!$B$2*100+10),SUMIFS('Sổ giao dịch'!$F$2:$F$3001,'Sổ giao dịch'!$C$2:$C$3001,A13,'Sổ giao dịch'!$H$2:$H$3001,'Thống kê tháng'!$B$2*100+10))) | M13: =IF(A13="","",IF(B13="Thu",SUMIFS('Sổ giao dịch'!$E$2:$E$3001,'Sổ giao dịch'!$C$2:$C$3001,A13,'Sổ giao dịch'!$H$2:$H$3001,'Thống kê tháng'!$B$2*100+11),SUMIFS('Sổ giao dịch'!$F$2:$F$3001,'Sổ giao dịch'!$C$2:$C$3001,A13,'Sổ giao dịch'!$H$2:$H$3001,'Thống kê tháng'!$B$2*100+11))) | N13: =IF(A13="","",IF(B13="Thu",SUMIFS('Sổ giao dịch'!$E$2:$E$3001,'Sổ giao dịch'!$C$2:$C$3001,A13,'Sổ giao dịch'!$H$2:$H$3001,'Thống kê tháng'!$B$2*100+12),SUMIFS('Sổ giao dịch'!$F$2:$F$3001,'Sổ giao dịch'!$C$2:$C$3001,A13,'Sổ giao dịch'!$H$2:$H$3001,'Thống kê tháng'!$B$2*100+12))) | O13: =IF(A13="","",SUM(C13:N13)) | P13: =IF(A13="","",IF('Thống kê tháng'!$B$19=0,0,O13/'Thống kê tháng'!$B$19)) | Q13: =IF(OR(A13="",'Danh mục'!C10=""),"",'Danh mục'!C10) | R13: =IF(OR(Q13="",Q13=0),"",P13/Q13)
A14: =IF('Danh mục'!A11="","",'Danh mục'!A11) | B14: =IF(A14="","",'Danh mục'!B11) | C14: =IF(A14="","",IF(B14="Thu",SUMIFS('Sổ giao dịch'!$E$2:$E$3001,'Sổ giao dịch'!$C$2:$C$3001,A14,'Sổ giao dịch'!$H$2:$H$3001,'Thống kê tháng'!$B$2*100+1),SUMIFS('Sổ giao dịch'!$F$2:$F$3001,'Sổ giao dịch'!$C$2:$C$3001,A14,'Sổ giao dịch'!$H$2:$H$3001,'Thống kê tháng'!$B$2*100+1))) | D14: =IF(A14="","",IF(B14="Thu",SUMIFS('Sổ giao dịch'!$E$2:$E$3001,'Sổ giao dịch'!$C$2:$C$3001,A14,'Sổ giao dịch'!$H$2:$H$3001,'Thống kê tháng'!$B$2*100+2),SUMIFS('Sổ giao dịch'!$F$2:$F$3001,'Sổ giao dịch'!$C$2:$C$3001,A14,'Sổ giao dịch'!$H$2:$H$3001,'Thống kê tháng'!$B$2*100+2))) | E14: =IF(A14="","",IF(B14="Thu",SUMIFS('Sổ giao dịch'!$E$2:$E$3001,'Sổ giao dịch'!$C$2:$C$3001,A14,'Sổ giao dịch'!$H$2:$H$3001,'Thống kê tháng'!$B$2*100+3),SUMIFS('Sổ giao dịch'!$F$2:$F$3001,'Sổ giao dịch'!$C$2:$C$3001,A14,'Sổ giao dịch'!$H$2:$H$3001,'Thống kê tháng'!$B$2*100+3))) | F14: =IF(A14="","",IF(B14="Thu",SUMIFS('Sổ giao dịch'!$E$2:$E$3001,'Sổ giao dịch'!$C$2:$C$3001,A14,'Sổ giao dịch'!$H$2:$H$3001,'Thống kê tháng'!$B$2*100+4),SUMIFS('Sổ giao dịch'!$F$2:$F$3001,'Sổ giao dịch'!$C$2:$C$3001,A14,'Sổ giao dịch'!$H$2:$H$3001,'Thống kê tháng'!$B$2*100+4))) | G14: =IF(A14="","",IF(B14="Thu",SUMIFS('Sổ giao dịch'!$E$2:$E$3001,'Sổ giao dịch'!$C$2:$C$3001,A14,'Sổ giao dịch'!$H$2:$H$3001,'Thống kê tháng'!$B$2*100+5),SUMIFS('Sổ giao dịch'!$F$2:$F$3001,'Sổ giao dịch'!$C$2:$C$3001,A14,'Sổ giao dịch'!$H$2:$H$3001,'Thống kê tháng'!$B$2*100+5))) | H14: =IF(A14="","",IF(B14="Thu",SUMIFS('Sổ giao dịch'!$E$2:$E$3001,'Sổ giao dịch'!$C$2:$C$3001,A14,'Sổ giao dịch'!$H$2:$H$3001,'Thống kê tháng'!$B$2*100+6),SUMIFS('Sổ giao dịch'!$F$2:$F$3001,'Sổ giao dịch'!$C$2:$C$3001,A14,'Sổ giao dịch'!$H$2:$H$3001,'Thống kê tháng'!$B$2*100+6))) | I14: =IF(A14="","",IF(B14="Thu",SUMIFS('Sổ giao dịch'!$E$2:$E$3001,'Sổ giao dịch'!$C$2:$C$3001,A14,'Sổ giao dịch'!$H$2:$H$3001,'Thống kê tháng'!$B$2*100+7),SUMIFS('Sổ giao dịch'!$F$2:$F$3001,'Sổ giao dịch'!$C$2:$C$3001,A14,'Sổ giao dịch'!$H$2:$H$3001,'Thống kê tháng'!$B$2*100+7))) | J14: =IF(A14="","",IF(B14="Thu",SUMIFS('Sổ giao dịch'!$E$2:$E$3001,'Sổ giao dịch'!$C$2:$C$3001,A14,'Sổ giao dịch'!$H$2:$H$3001,'Thống kê tháng'!$B$2*100+8),SUMIFS('Sổ giao dịch'!$F$2:$F$3001,'Sổ giao dịch'!$C$2:$C$3001,A14,'Sổ giao dịch'!$H$2:$H$3001,'Thống kê tháng'!$B$2*100+8))) | K14: =IF(A14="","",IF(B14="Thu",SUMIFS('Sổ giao dịch'!$E$2:$E$3001,'Sổ giao dịch'!$C$2:$C$3001,A14,'Sổ giao dịch'!$H$2:$H$3001,'Thống kê tháng'!$B$2*100+9),SUMIFS('Sổ giao dịch'!$F$2:$F$3001,'Sổ giao dịch'!$C$2:$C$3001,A14,'Sổ giao dịch'!$H$2:$H$3001,'Thống kê tháng'!$B$2*100+9))) | L14: =IF(A14="","",IF(B14="Thu",SUMIFS('Sổ giao dịch'!$E$2:$E$3001,'Sổ giao dịch'!$C$2:$C$3001,A14,'Sổ giao dịch'!$H$2:$H$3001,'Thống kê tháng'!$B$2*100+10),SUMIFS('Sổ giao dịch'!$F$2:$F$3001,'Sổ giao dịch'!$C$2:$C$3001,A14,'Sổ giao dịch'!$H$2:$H$3001,'Thống kê tháng'!$B$2*100+10))) | M14: =IF(A14="","",IF(B14="Thu",SUMIFS('Sổ giao dịch'!$E$2:$E$3001,'Sổ giao dịch'!$C$2:$C$3001,A14,'Sổ giao dịch'!$H$2:$H$3001,'Thống kê tháng'!$B$2*100+11),SUMIFS('Sổ giao dịch'!$F$2:$F$3001,'Sổ giao dịch'!$C$2:$C$3001,A14,'Sổ giao dịch'!$H$2:$H$3001,'Thống kê tháng'!$B$2*100+11))) | N14: =IF(A14="","",IF(B14="Thu",SUMIFS('Sổ giao dịch'!$E$2:$E$3001,'Sổ giao dịch'!$C$2:$C$3001,A14,'Sổ giao dịch'!$H$2:$H$3001,'Thống kê tháng'!$B$2*100+12),SUMIFS('Sổ giao dịch'!$F$2:$F$3001,'Sổ giao dịch'!$C$2:$C$3001,A14,'Sổ giao dịch'!$H$2:$H$3001,'Thống kê tháng'!$B$2*100+12))) | O14: =IF(A14="","",SUM(C14:N14)) | P14: =IF(A14="","",IF('Thống kê tháng'!$B$19=0,0,O14/'Thống kê tháng'!$B$19)) | Q14: =IF(OR(A14="",'Danh mục'!C11=""),"",'Danh mục'!C11) | R14: =IF(OR(Q14="",Q14=0),"",P14/Q14)
A15: =IF('Danh mục'!A12="","",'Danh mục'!A12) | B15: =IF(A15="","",'Danh mục'!B12) | C15: =IF(A15="","",IF(B15="Thu",SUMIFS('Sổ giao dịch'!$E$2:$E$3001,'Sổ giao dịch'!$C$2:$C$3001,A15,'Sổ giao dịch'!$H$2:$H$3001,'Thống kê tháng'!$B$2*100+1),SUMIFS('Sổ giao dịch'!$F$2:$F$3001,'Sổ giao dịch'!$C$2:$C$3001,A15,'Sổ giao dịch'!$H$2:$H$3001,'Thống kê tháng'!$B$2*100+1))) | D15: =IF(A15="","",IF(B15="Thu",SUMIFS('Sổ giao dịch'!$E$2:$E$3001,'Sổ giao dịch'!$C$2:$C$3001,A15,'Sổ giao dịch'!$H$2:$H$3001,'Thống kê tháng'!$B$2*100+2),SUMIFS('Sổ giao dịch'!$F$2:$F$3001,'Sổ giao dịch'!$C$2:$C$3001,A15,'Sổ giao dịch'!$H$2:$H$3001,'Thống kê tháng'!$B$2*100+2))) | E15: =IF(A15="","",IF(B15="Thu",SUMIFS('Sổ giao dịch'!$E$2:$E$3001,'Sổ giao dịch'!$C$2:$C$3001,A15,'Sổ giao dịch'!$H$2:$H$3001,'Thống kê tháng'!$B$2*100+3),SUMIFS('Sổ giao dịch'!$F$2:$F$3001,'Sổ giao dịch'!$C$2:$C$3001,A15,'Sổ giao dịch'!$H$2:$H$3001,'Thống kê tháng'!$B$2*100+3))) | F15: =IF(A15="","",IF(B15="Thu",SUMIFS('Sổ giao dịch'!$E$2:$E$3001,'Sổ giao dịch'!$C$2:$C$3001,A15,'Sổ giao dịch'!$H$2:$H$3001,'Thống kê tháng'!$B$2*100+4),SUMIFS('Sổ giao dịch'!$F$2:$F$3001,'Sổ giao dịch'!$C$2:$C$3001,A15,'Sổ giao dịch'!$H$2:$H$3001,'Thống kê tháng'!$B$2*100+4))) | G15: =IF(A15="","",IF(B15="Thu",SUMIFS('Sổ giao dịch'!$E$2:$E$3001,'Sổ giao dịch'!$C$2:$C$3001,A15,'Sổ giao dịch'!$H$2:$H$3001,'Thống kê tháng'!$B$2*100+5),SUMIFS('Sổ giao dịch'!$F$2:$F$3001,'Sổ giao dịch'!$C$2:$C$3001,A15,'Sổ giao dịch'!$H$2:$H$3001,'Thống kê tháng'!$B$2*100+5))) | H15: =IF(A15="","",IF(B15="Thu",SUMIFS('Sổ giao dịch'!$E$2:$E$3001,'Sổ giao dịch'!$C$2:$C$3001,A15,'Sổ giao dịch'!$H$2:$H$3001,'Thống kê tháng'!$B$2*100+6),SUMIFS('Sổ giao dịch'!$F$2:$F$3001,'Sổ giao dịch'!$C$2:$C$3001,A15,'Sổ giao dịch'!$H$2:$H$3001,'Thống kê tháng'!$B$2*100+6))) | I15: =IF(A15="","",IF(B15="Thu",SUMIFS('Sổ giao dịch'!$E$2:$E$3001,'Sổ giao dịch'!$C$2:$C$3001,A15,'Sổ giao dịch'!$H$2:$H$3001,'Thống kê tháng'!$B$2*100+7),SUMIFS('Sổ giao dịch'!$F$2:$F$3001,'Sổ giao dịch'!$C$2:$C$3001,A15,'Sổ giao dịch'!$H$2:$H$3001,'Thống kê tháng'!$B$2*100+7))) | J15: =IF(A15="","",IF(B15="Thu",SUMIFS('Sổ giao dịch'!$E$2:$E$3001,'Sổ giao dịch'!$C$2:$C$3001,A15,'Sổ giao dịch'!$H$2:$H$3001,'Thống kê tháng'!$B$2*100+8),SUMIFS('Sổ giao dịch'!$F$2:$F$3001,'Sổ giao dịch'!$C$2:$C$3001,A15,'Sổ giao dịch'!$H$2:$H$3001,'Thống kê tháng'!$B$2*100+8))) | K15: =IF(A15="","",IF(B15="Thu",SUMIFS('Sổ giao dịch'!$E$2:$E$3001,'Sổ giao dịch'!$C$2:$C$3001,A15,'Sổ giao dịch'!$H$2:$H$3001,'Thống kê tháng'!$B$2*100+9),SUMIFS('Sổ giao dịch'!$F$2:$F$3001,'Sổ giao dịch'!$C$2:$C$3001,A15,'Sổ giao dịch'!$H$2:$H$3001,'Thống kê tháng'!$B$2*100+9))) | L15: =IF(A15="","",IF(B15="Thu",SUMIFS('Sổ giao dịch'!$E$2:$E$3001,'Sổ giao dịch'!$C$2:$C$3001,A15,'Sổ giao dịch'!$H$2:$H$3001,'Thống kê tháng'!$B$2*100+10),SUMIFS('Sổ giao dịch'!$F$2:$F$3001,'Sổ giao dịch'!$C$2:$C$3001,A15,'Sổ giao dịch'!$H$2:$H$3001,'Thống kê tháng'!$B$2*100+10))) | M15: =IF(A15="","",IF(B15="Thu",SUMIFS('Sổ giao dịch'!$E$2:$E$3001,'Sổ giao dịch'!$C$2:$C$3001,A15,'Sổ giao dịch'!$H$2:$H$3001,'Thống kê tháng'!$B$2*100+11),SUMIFS('Sổ giao dịch'!$F$2:$F$3001,'Sổ giao dịch'!$C$2:$C$3001,A15,'Sổ giao dịch'!$H$2:$H$3001,'Thống kê tháng'!$B$2*100+11))) | N15: =IF(A15="","",IF(B15="Thu",SUMIFS('Sổ giao dịch'!$E$2:$E$3001,'Sổ giao dịch'!$C$2:$C$3001,A15,'Sổ giao dịch'!$H$2:$H$3001,'Thống kê tháng'!$B$2*100+12),SUMIFS('Sổ giao dịch'!$F$2:$F$3001,'Sổ giao dịch'!$C$2:$C$3001,A15,'Sổ giao dịch'!$H$2:$H$3001,'Thống kê tháng'!$B$2*100+12))) | O15: =IF(A15="","",SUM(C15:N15)) | P15: =IF(A15="","",IF('Thống kê tháng'!$B$19=0,0,O15/'Thống kê tháng'!$B$19)) | Q15: =IF(OR(A15="",'Danh mục'!C12=""),"",'Danh mục'!C12) | R15: =IF(OR(Q15="",Q15=0),"",P15/Q15)
